Workbook

Sheet Read Me
C2: Sheet | D2: Records | E2: What does it cover
C3: Raw Data | D3: 1647 | E3: Export of 1,647 references in Zotero is from IPBES Global Assessment 1, Chapter 2.1. Chapter 2.1 (Status and Trends - Drivers of Change) discusses the indirect and direct drivers of biodiversity loss, as well as associated development pathways.
C4: Enriched Data | D4: 1647 | E4: Manually annotated all 228 references as ‘Y’ when they were found in Chapters 2.1.12 - 2.1.17, i.e., the chapters related to the direct drivers of biodiversity loss. Additionally, if these annotated references were present in Web of Science, they were also marked as ‘Y’.
C5: Curated Data | D5: 156 | E5: From all annotated references, select only those present in Chapters 2.1.12–2.1.17 (156 in total), while excluding references from grey literature (57 in total) and those that do not exist in Web of Science (15 in total).
C6: Query | D6: 119 | E6: Web of Science query to get all records of References Selected in test list

Sheet WOS Search for References
A1: Publication Type | B1: Authors | C1: Article Title | D1: Source Title | E1: Document Type | F1: Abstract | G1: DOI | H1: DOI Link | I1: WoS Categories | J1: Date of Export | K1: UT (Unique WOS ID) | L1: Web of Science Record
A2: J | B2: Lambdon, PW; Pysek, P; Basnou, C; Hejda, M; Arianoutsou, M; Essl, F; Jarosik, V; Pergl, J; Winter, M; Anastasiu, P; Andriopoulos, P; Bazos, I; Brundu, G; Celesti-Grapow, L; Chassot, P; Delipetrou, P; Josefsson, M; Kark, S; Klotz, S; Kokkoris, Y; Kühn, I; Marchante, H; Perglová, I; Pino, J; Vilà, M; Zikos, A; Roy, D; Hulme, PE | C2: Alien flora of Europe:: species diversity, temporal trends, geographical patterns and research needs | D2: PRESLIA | E2: Review | F2: The paper provides the first estimate of the composition and structure of alien plants occurring in the wild in the European continent, based on the results of the DAISIE project (2004-2008), funded by the 6th Framework Programme of the European Union and aimed at creating an inventory of invasive species that threaten European terrestrial, freshwater and marine environments. The plant section of the DAISIE database is based on national checklists from 48 European countries/regions and Israel; for many of them the data were compiled during the project and for some countries DAISIE collected the first comprehensive checklists of alien species, based on primary data (e.g., Cyprus, Greece, R Y. R. O. Macedonia, Slovenia, Ukraine). In total, the database contains records of 5789 alien plant species in Europe (including those native to a part of Europe but alien to another part), of which 2843 are alien to Europe (of extra-European origin). The research focus was on naturalized species; there are in total 3749 naturalized aliens in Europe, of which 1780 are alien to Europe. This represents a marked increase compared to 1568 alien species reported by a previous analysis of data in Flora Europaea (1964-1980). Casual aliens were marginally considered and are represented by 1507 species with European origins and 872 species whose native range falls outside Europe. The highest diversity of alien species is concentrated in industrialized countries with a tradition of good botanical recording or intensive recent research. The highest number of all alien species, regardless of status, is reported from Belgium (1969), the United Kingdom (1779) and Czech Republic (1378). The United Kingdom (857), Germany (450), Belgium (447) and Italy (440) are countries with the most naturalized neophytes. The number of naturalized neophytes in European countries is determined mainly by the interaction of temperature and precipitation; it increases with increasing precipitation but only in climatically warm and moderately warm regions. Of the nowadays naturalized neophytes alien to Europe, 50% arrived after 1899, 25% after 1962 and 10% after 1989. At present, approximately 6.2 new species, that are capable of naturalization, are arriving each year. Most alien species have relatively restricted European distributions; half of all naturalized species occur in four or fewer countries/regions, whereas 70% of non-naturalized species occur in only one region. Alien species are drawn from 213 families, dominated by large global plant families which have a weedy tendency and have undergone major radiations in temperate regions (Asteraceae, Poaceae, Rosaceae, Fabaceae, Brassicaceae). There are 1567 genera, which have alien members in European countries, the commonest being globally-diverse genera comprising mainly urban and agricultural weeds (e.g., Amaranthus, Chenopodium and Solanum) or cultivated for ornamental purposes (Cotoneaster, the genus richest in alien species). Only a few large genera which have successfully invaded (e.g., Oenothera, Oxalis, Panicum, Helianthus) are predominantly of non-European origin. Conyza canadensis, Helianthus tuberosus and Robinia pseudoacacia are most widely distributed alien species. Of all naturalized aliens present in Europe, 64.1% occur in industrial habitats and 58.5% on arable land and in parks and gardens. Grasslands and woodlands are also highly invaded, with 37.4 and 31.5%, respectively, of all naturalized aliens in Europe present in these habitats. Mires, bogs and fens are least invaded; only approximately 10% of aliens in Euope occur there. Intentional introductions to Europe (62.8% of the total number of naturalized aliens) prevail over unintentional (37.2%). Ornamental and horticultural introductions escaped from cultivation account for the highest number of species, 52.2% of the total. Among unintentional introductions, contaminants of seed, mineral materials and other commodities are responsible for 1091 alien species introductions to Europe (76.6% of all species introduced unintentionally) and 363 species are assumed to have arrived as stowaways (directly associated with human transport but arriving independently of commodity). Most aliens in Europe have a native range in the same continent (28.6% of all donor region records are from another part of Europe where the plant is native); in terms of species numbers the contribution of Europe as a region of origin is 53.2%. Considering aliens to Europe separately, 45.8% of species have their native distribution in North and South America, 45.9% in Asia, 20.7% in Africa and 5.3% in Australasia. Based on species composition, European alien flora can be classified into five major groups: (1) north-western, comprising Scandinavia and the UK; (2) west-central, extending from Belgium and the Netherlands to Germany and Switzerland; (3) Baltic, including only the former Soviet Baltic states; (4) east-central, comprizing the remainder of central and eastern Europe; (5) southern, covering the entire Mediterranean region. The clustering patterns cut across some European bioclimatic zones; cultural factors such as regional trade links and traditional local preferences for crop, forestry and ornamental species are also important by influencing the introduced species pool. Finally, the paper evaluates a state of the art in the field of plant invasions in Europe, points to research gaps and outlines avenues of further research towards documenting alien plant invasions in Europe. The data are of varying quality and need to be further assessed with respect to the invasion status and residence time of the species included. This concerns especially the naturalized/casual status; so far, this information is available comprehensively for only 19 countries/regions of the 49 considered. Collating an integrated database on the alien flora of Europe can form a principal contribution to developing a European-wide management strategy of alien species. | I2: Plant Sciences | J2: 45982 | K2: WOS:000258002600001 | L2: View Full Record in Web of Science
A3: J | B3: Seebens, H; Blackburn, TM; Dyer, EE; Genovesi, P; Hulme, PE; Jeschke, JM; Pagad, S; Pysek, P; van Kleunen, M; Winter, M; Ansong, M; Arianoutsou, M; Bacher, S; Blasius, B; Brockerhoff, EG; Brundu, G; Capinha, C; Causton, CE; Celesti-Grapow, L; Dawson, W; Dullinger, S; Economo, EP; Fuentes, N; Guénard, B; Jäger, H; Kartesz, J; Kenis, M; Kühn, I; Lenzner, B; Liebhold, AM; Mosena, A; Moser, D; Nentwig, W; Nishino, M; Pearman, D; Pergl, J; Rabitsch, W; Rojas-Sandoval, J; Roques, A; Rorke, S; Rossinelli, S; Roy, HE; Scalera, R; Schindler, S; Stajerová, K; Tokarska-Guzik, B; Walker, K; Ward, DF; Yamanaka, T; Essl, F | C3: Global rise in emerging alien species results from increased accessibility of new source pools | D3: PROCEEDINGS OF THE NATIONAL ACADEMY OF SCIENCES OF THE UNITED STATES OF AMERICA | E3: Article | F3: Our ability to predict the identity of future invasive alien species is largely based upon knowledge of prior invasion history. Emerging alien species-those never encountered as aliens before-therefore pose a significant challenge to biosecurity interventions worldwide. Understanding their temporal trends, origins, and the drivers of their spread is pivotal to improving prevention and risk assessment tools. Here, we use a database of 45,984 first records of 16,019 established alien species to investigate the temporal dynamics of occurrences of emerging alien species worldwide. Even after many centuries of invasions the rate of emergence of new alien species is still high: Onequarter of first records during 2000-2005 were of species that had not been previously recorded anywhere as alien, though with large variation across taxa. Model results show that the high proportion of emerging alien species cannot be solely explained by increases in well-known drivers such as the amount of imported commodities from historically important source regions. Instead, these dynamics reflect the incorporation of new regions into the pool of potential alien species, likely as a consequence of expanding trade networks and environmental change. This process compensates for the depletion of the historically important source species pool through successive invasions. We estimate that 1-16% of all species on Earth, depending on the taxonomic group, qualify as potential alien species. These results suggest that there remains a high proportion of emerging alien species we have yet to encounter, with future impacts that are difficult to predict. | G3: 10.1073/pnas.1719429115 | H3: http://dx.doi.org/10.1073/pnas.1719429115 | I3: Multidisciplinary Sciences | J3: 45982 | K3: WOS:000426671900017 | L3: View Full Record in Web of Science
A4: J | B4: Newman, M; Wittenberg, AT; Cheng, LY; Compo, GP; Smith, CA | C4: THE EXTREME 2015/16 EL NINO, IN THE CONTEXT OF HISTORICAL CLIMATE VARIABILITY AND CHANGE | D4: BULLETIN OF THE AMERICAN METEOROLOGICAL SOCIETY | E4: Article | G4: 10.1175/BAMS-D-17-0116.1 | H4: http://dx.doi.org/10.1175/BAMS-D-17-0116.1 | I4: Meteorology & Atmospheric Sciences | J4: 45982 | K4: WOS:000429319000004 | L4: View Full Record in Web of Science
A5: J | B5: Risser, MD; Wehner, MF | C5: Attributable Human-Induced Changes in the Likelihood and Magnitude of the Observed Extreme Precipitation during Hurricane Harvey | D5: GEOPHYSICAL RESEARCH LETTERS | E5: Article | F5: Record rainfall amounts were recorded during Hurricane Harvey in the Houston, Texas, area, leading to widespread flooding. We analyze observed precipitation from the Global Historical Climatology Network with a covariate-based extreme value statistical analysis, accounting for both the external influence of global warming and the internal influence of El Nino-Southern Oscillation. We find that human-induced climate change likely increased the chances of the observed precipitation accumulations during Hurricane Harvey in the most affected areas of Houston by a factor of at least 3.5. Further, precipitation accumulations in these areas were likely increased by at least 18.8% (best estimate of 37.7%), which is larger than the 6-7% associated with an attributable warming of 1 degrees C in the Gulf of Mexico and Clausius-Clapeyron scaling. In a Granger causality sense, these statements provide lower bounds on the impact of climate change and motivate further attribution studies using dynamical climate models. | G5: 10.1002/2017GL075888 | H5: http://dx.doi.org/10.1002/2017GL075888 | I5: Geosciences, Multidisciplinary | J5: 45982 | K5: WOS:000422954700032 | L5: View Full Record in Web of Science
A6: J | B6: Johnson, AC; Donnachie, RL; Sumpter, JP; Jurgens, MD; Moeckel, C; Pereira, MG | C6: An alternative approach to risk rank chemicals on the threat they pose to the aquatic environment | D6: SCIENCE OF THE TOTAL ENVIRONMENT | E6: Article | F6: This work presents a new and unbiased method of risk ranking chemicals based on the threat they pose to the aquatic environment. The study ranked 12 metals, 23 pesticides, 11 other persistent organic pollutants (POPs), 13 pharmaceuticals, 10 surfactants and similar compounds and 2 nanoparticles (total of 71) of concern against one another by comparing their median UK river water and median ecotoxicity effect concentrations. To complement this, by giving an assessment on potential wildlife impacts, risk ranking was also carried out by comparing the lowest 10th percentile of the effects data with the highest 90th percentile of the exposure data. In other words, risk was pared down to just toxicity versus exposure. Further modifications included incorporating bioconcentration factors, using only recent water measurements and excluding either lethal or sub-lethal effects. The top ten chemicals, based on the medians, which emerged as having the highest risk to organisms in UK surface waters using all the ecotoxicity data were copper, aluminium, zinc, ethinylestradiol (EE2), linear alkylbenzene sulfonate (LAS), triclosan, manganese, iron, methomyl and chlorpyrifos. By way of contrast, using current UK environmental quality standards as the comparator to median UK river water concentrations would have selected 6 different chemicals in the top ten. This approach revealed big differences in relative risk; for example, zinc presented a million times greater risk then metoprolol and LAS 550 times greater risk than nanosilver. With the exception of EE2, most pharmaceuticals were ranked as having a relatively low risk. (C) 2017 Elsevier B.V. All rights reserved. | G6: 10.1016/j.scitotenv.2017.05.039 | H6: http://dx.doi.org/10.1016/j.scitotenv.2017.05.039 | I6: Environmental Sciences | J6: 45982 | K6: WOS:000405253500033 | L6: View Full Record in Web of Science
A7: J | B7: Emanuel, K | C7: Assessing the present and future probability of Hurricane Harvey's rainfall | D7: PROCEEDINGS OF THE NATIONAL ACADEMY OF SCIENCES OF THE UNITED STATES OF AMERICA | E7: Article | F7: We estimate, for current and future climates, the annual probability of areally averaged hurricane rain of Hurricane Harvey's magnitude by downscaling large numbers of tropical cyclones from three climate reanalyses and six climate models. For the state of Texas, we estimate that the annual probability of 500 mm of area-integrated rainfall was about 1% in the period 1981-2000 and will increase to 18% over the period 2081-2100 under Intergovernmental Panel on Climate Change (IPCC) AR5 representative concentration pathway 8.5. If the frequency of such event is increasingly linearly between these two periods, then in 2017 the annual probability would be 6%, a sixfold increase since the late 20th century. | G7: 10.1073/pnas.1716222114 | H7: http://dx.doi.org/10.1073/pnas.1716222114 | I7: Multidisciplinary Sciences | J7: 45982 | K7: WOS:000416891600045 | L7: View Full Record in Web of Science
A8: J | B8: Dawson, W; Moser, D; van Kleunen, M; Kreft, H; Pergl, J; Pysek, P; Weigelt, P; Winter, M; Lenzner, B; Blackburn, TM; Dyer, EE; Cassey, P; Scrivens, SL; Economo, EP; Guénard, B; Capinha, C; Seebens, H; García-Díaz, P; Nentwig, W; García-Berthou, E; Casal, C; Mandrak, NE; Fuller, P; Meyer, C; Essl, F | C8: Global hotspots and correlates of alien species richness across taxonomic groups | D8: NATURE ECOLOGY & EVOLUTION | E8: Article | F8: Human-mediated transport beyond biogeographic barriers has led to the introduction and establishment of alien species in new regions worldwide. However, we lack a global picture of established alien species richness for multiple taxonomic groups. Here, we assess global patterns and potential drivers of established alien species richness across eight taxonomic groups (amphibians, ants, birds, freshwater fishes, mammals, vascular plants, reptiles and spiders) for 186 islands and 423 mainland regions. Hotspots of established alien species richness are predominantly island and coastal mainland regions. Regions with greater gross domestic product per capita, human population density, and area have higher established alien richness, with strongest effects emerging for islands. Ants and reptiles, birds and mammals, and vascular plants and spiders form pairs of taxonomic groups with the highest spatial congruence in established alien richness, but drivers explaining richness differ between the taxa in each pair. Across all taxonomic groups, our results highlight the need to prioritize prevention of further alien species introductions to island and coastal mainland regions globally. | G8: 10.1038/s41559-017-0186 | H8: http://dx.doi.org/10.1038/s41559-017-0186 | I8: Ecology; Evolutionary Biology | J8: 45982 | K8: WOS:000417179000015 | L8: View Full Record in Web of Science
A9: J | B9: Geyer, R; Jambeck, JR; Law, KL | C9: Production, use, and fate of all plastics ever made | D9: SCIENCE ADVANCES | E9: Article | F9: Plastics have outgrown most man-made materials and have long been under environmental scrutiny. However, robust global information, particularly about their end-of-life fate, is lacking. By identifying and synthesizing dispersed data on production, use, and end-of-life management of polymer resins, synthetic fibers, and additives, we present the first global analysis of all mass-produced plastics ever manufactured. We estimate that 8300 million metric tons (Mt) as of virgin plastics have been produced to date. As of 2015, approximately 6300 Mt of plastic waste had been generated, around 9% of which had been recycled, 12% was incinerated, and 79% was accumulated in landfills or the natural environment. If current production and waste management trends continue, roughly 12,000 Mt of plastic waste will be in landfills or in the natural environment by 2050. | G9: 10.1126/sciadv.1700782 | H9: http://dx.doi.org/10.1126/sciadv.1700782 | I9: Multidisciplinary Sciences | J9: 45982 | K9: WOS:000411588000033 | L9: View Full Record in Web of Science
A10: J | B10: L'Heureux, ML; Takahashi, K; Watkins, AB; Barnston, AG; Becker, EJ; Di Liberto, TE; Gamble, F; Gottschalck, J; Halpert, MS; Huang, BY; Mosquera-Väsquez, K; Wittenberg, AT | C10: OBSERVING AND PREDICTING THE 2015/16 EL NINO | D10: BULLETIN OF THE AMERICAN METEOROLOGICAL SOCIETY | E10: Article | F10: The El Nino of 2015/16 rivaled the major El Nino events of 1982/83 and 1997/98, showcasing advancements in operational observing and prediction systems, while offering challenges for the future. | G10: 10.1175/BAMS-D-16-0009.1 | H10: http://dx.doi.org/10.1175/BAMS-D-16-0009.1 | I10: Meteorology & Atmospheric Sciences | J10: 45982 | K10: WOS:000406502800006 | L10: View Full Record in Web of Science
A11: J | B11: Lebreton, LCM; Van der Zwet, J; Damsteeg, JW; Slat, B; Andrady, A; Reisser, J | C11: River plastic emissions to the world's oceans | D11: NATURE COMMUNICATIONS | E11: Article | F11: Plastics in the marine environment have become a major concern because of their persistence at sea, and adverse consequences to marine life and potentially human health. Implementing mitigation strategies requires an understanding and quantification of marine plastic sources, taking spatial and temporal variability into account. Here we present a global model of plastic inputs from rivers into oceans based on waste management, population density and hydrological information. Our model is calibrated against measurements available in the literature. We estimate that between 1.15 and 2.41 million tonnes of plastic waste currently enters the ocean every year from rivers, with over 74% of emissions occurring between May and October. The top 20 polluting rivers, mostly located in Asia, account for 67% of the global total. The findings of this study provide baseline data for ocean plastic mass balance exercises, and assist in prioritizing future plastic debris monitoring and mitigation strategies. | G11: 10.1038/ncomms15611 | H11: http://dx.doi.org/10.1038/ncomms15611 | I11: Multidisciplinary Sciences | J11: 45982 | K11: WOS:000402803800001 | L11: View Full Record in Web of Science
A12: J | B12: Altieri, AH; Harrison, SB; Seemann, J; Collin, R; Diaz, RJ; Knowlton, N | C12: Tropical dead zones and mass mortalities on coral reefs | D12: PROCEEDINGS OF THE NATIONAL ACADEMY OF SCIENCES OF THE UNITED STATES OF AMERICA | E12: Article | F12: Degradation of coastal water quality in the form of low dissolved oxygen levels (hypoxia) can harm biodiversity, ecosystem function, and human wellbeing. Extreme hypoxic conditions along the coast, leading to what are often referred to as dead zones, are known primarily from temperate regions. However, little is known about the potential threat of hypoxia in the tropics, even though the known risk factors, including eutrophication and elevated temperatures, are common. Here we document an unprecedented hypoxic event on the Caribbean coast of Panama and assess the risk of dead zones to coral reefs worldwide. The event caused coral bleaching and massive mortality of corals and other reef-associated organisms, but observed shifts in community structure combined with laboratory experiments revealed that not all coral species are equally sensitive to hypoxia. Analyses of global databases showed that coral reefs are associated with more than half of the known tropical dead zones worldwide, with >10% of all coral reefs at elevated risk for hypoxia based on local and global risk factors. Hypoxic events in the tropics and associated mortality events have likely been underreported, perhaps by an order of magnitude, because of the lack of local scientific capacity for their detection. Monitoring and management plans for coral reef resilience should incorporate the growing threat of coastal hypoxia and include support for increased detection and research capacity. | G12: 10.1073/pnas.1621517114 | H12: http://dx.doi.org/10.1073/pnas.1621517114 | I12: Multidisciplinary Sciences | J12: 45982 | K12: WOS:000398159000048 | L12: View Full Record in Web of Science
A13: J | B13: Seebens, H; Blackburn, TM; Dyer, EE; Genovesi, P; Hulme, PE; Jeschke, JM; Pagad, S; Pysek, P; Winter, M; Arianoutsou, M; Bacher, S; Blasius, B; Brundu, G; Capinha, C; Celesti-Grapow, L; Dawson, W; Dullinger, S; Fuentes, N; Jäger, H; Kartesz, J; Kenis, M; Kreft, H; Kühn, I; Lenzner, B; Liebhold, A; Mosena, A; Moser, D; Nishino, M; Pearman, D; Pergl, J; Rabitsch, W; Rojas-Sandoval, J; Roques, A; Rorke, S; Rossinelli, S; Roy, HE; Scalera, R; Schindler, S; Stajerová, K; Tokarska-Guzik, B; van Kleunen, M; Walker, K; Weigelt, P; Yamanaka, T; Essl, F | C13: No saturation in the accumulation of alien species worldwide | D13: NATURE COMMUNICATIONS | E13: Article | F13: Although research on human-mediated exchanges of species has substantially intensified during the last centuries, we know surprisingly little about temporal dynamics of alien species accumulations across regions and taxa. Using a novel database of 45,813 first records of 16,926 established alien species, we show that the annual rate of first records worldwide has increased during the last 200 years, with 37% of all first records reported most recently (1970-2014). Inter-continental and inter-taxonomic variation can be largely attributed to the diaspora of European settlers in the nineteenth century and to the acceleration in trade in the twentieth century. For all taxonomic groups, the increase in numbers of alien species does not show any sign of saturation and most taxa even show increases in the rate of first records over time. This highlights that past efforts to mitigate invasions have not been effective enough to keep up with increasing globalization. | G13: 10.1038/ncomms14435 | H13: http://dx.doi.org/10.1038/ncomms14435 | I13: Multidisciplinary Sciences | J13: 45982 | K13: WOS:000394221600001 | L13: View Full Record in Web of Science
A14: J | B14: Arroita, M; Flores, L; Larrañaga, A; Martínez, A; Martínez-Santos, M; Pereda, O; Ruiz-Romera, E; Solagaistua, L; Elosegi, A | C14: Water abstraction impacts stream ecosystem functioning via wetted-channel contraction | D14: FRESHWATER BIOLOGY | E14: Article | F14: Water abstraction is rapidly increasing worldwide in order to respond to escalating demands for water, food and energy. Abstraction can alter the hydrological regime of streams and rivers, reduce in-stream habitats, change water quality and affect fluvial communities. It can also impair ecosystem functioning, although this aspect has been seldom assessed. We experimentally tested the effect of water abstraction on stream functioning in a headwater mountain stream using a before and after control-impact (BACI) design. We quantified changes in water physicochemical properties, biofilm biomass and activity (exo-enzymes and metabolism), and ecosystem processes (nutrient cycling, organic matter retention and breakdown). Water abstraction did not affect water physicochemical properties, but reduced the biomass and the alkaline phosphatase activity of biofilm per surface unit, the areal uptake of nutrients, and the travel distance of organic matter. It did not affect the biofilm metabolism and breakdown of submerged leaf litter, but decreased the total breakdown. The impacts were larger when analysed per unit of channel length. All variables, except benthic chlorophyll-a, were significantly reduced by abstraction, due to the contraction of the wetted channel. The decrease in the biomass and activity of biofilm, as well as in nutrient uptake and total organic matter breakdown observed in this study could increase nutrient concentration in downstream reaches and reduce the energy transfer to higher trophic levels. Ecosystem services of permanent headwater streams are likely to be compromised with the reduction of wetted-channel width. | G14: 10.1111/fwb.12864 | H14: http://dx.doi.org/10.1111/fwb.12864 | I14: Ecology; Marine & Freshwater Biology | J14: 45982 | K14: WOS:000393793100003 | L14: View Full Record in Web of Science
A15: J | B15: Hattich, GSI; Listmann, L; Raab, J; Ozod-Seradj, D; Reusch, TBH; Matthiessen, B | C15: Inter- and intraspecific phenotypic plasticity of three phytoplankton species in response to ocean acidification | D15: BIOLOGY LETTERS | E15: Article | F15: Phenotypic plasticity describes the phenotypic adjustment of the same genotype to different environmental conditions and is best described by a reaction norm. We focus on the effect of ocean acidification on inter-and intraspecific reaction norms of three globally important phytoplankton species (Emiliania huxleyi, Gephyrocapsa oceanica and Chaetoceros affinis). Despite significant differences in growth rates between the species, they all showed a high potential for phenotypic buffering (similar growth rates between ambient and high CO2 conditions). Only three coccolithophore genotypes showed a reduced growth in high CO2. Diverging responses to high CO2 of single coccolithophore genotypes compared with the respective mean species responses, however, raise the question of whether an extrapolation to the population level is possible from single-genotype experiments. We therefore compared the mean response of all tested genotypes with a total species response comprising the same genotypes, which was not significantly different in the coccolithophores. Assessing species reaction norms to different environmental conditions on short time scale in a genotype-mix could thus reduce sampling effort while increasing predictive power. | G15: 10.1098/rsbl.2016.0774 | H15: http://dx.doi.org/10.1098/rsbl.2016.0774 | I15: Biology; Ecology; Evolutionary Biology | J15: 45982 | K15: WOS:000396015400004 | L15: View Full Record in Web of Science
A16: J | B16: Hoegh-Guldberg, O; Poloczanska, ES; Skirving, W; Dove, S | C16: Coral Reef Ecosystems under Climate Change and Ocean Acidification | D16: FRONTIERS IN MARINE SCIENCE | E16: Review | F16: Coral reefs are found in a wide range of environments, where they provide food and habitat to a large range of organisms as well as providing many other ecological goods and services. Warm-water coral reefs, for example, occupy shallow sunlit, warm, and alkaline waters in order to grow and calcify at the high rates necessary to build and maintain their calcium carbonate structures. At deeper locations (40-150 m), mesophotic (low light) coral reefs accumulate calcium carbonate at much lower rates (if at all in some cases) yet remain important as habitat for a wide range of organisms, including those important for fisheries. Finally, even deeper, down to 2,000 m or more, the so-called cold-water coral reefs are found in the dark depths. Despite their importance, coral reefs are facing significant challenges from human activities including pollution, over-harvesting, physical destruction, and climate change. In the latter case, even lower greenhouse gas emission scenarios (such as Representative Concentration Pathway RCP 4.5) are likely drive the elimination of most warm-water coral reefs by 2040-2050. Cold-water corals are also threatened by warming temperatures and ocean acidification although evidence of the direct effect of climate change is less clear. Evidence that coral reefs can adapt at rates which are sufficient for them to keep up with rapid ocean warming and acidification is minimal, especially given that corals are long-lived and hence have slow rates of evolution. Conclusions that coral reefs will migrate to higher latitudes as they warm are equally unfounded, with the observations of tropical species appearing at high latitudes necessary but not sufficient evidence that entire coral reef ecosystems are shifting. On the contrary, coral reefs are likely to degrade rapidly over the next 20 years, presenting fundamental challenges for the 500 million people who derive food, income, coastal protection, and a range of other services from coral reefs. Unless rapid advances to the goals of the Paris Climate Change Agreement occur over the next decade, hundreds of millions of people are likely to face increasing amounts of poverty and social disruption, and, in some cases, regional insecurity. | G16: 10.3389/fmars.2017.00158 | H16: http://dx.doi.org/10.3389/fmars.2017.00158 | I16: Environmental Sciences; Marine & Freshwater Biology | J16: 45982 | K16: WOS:000457690600158 | L16: View Full Record in Web of Science
... A59: J | B59: Nepstad, D; McGrath, D; Stickler, C; Alencar, A; Azevedo, A; Swette, B; Bezerra, T; DiGiano, M; Shimada, J; da Motta, RS; Armijo, E; Castello, L; Brando, P; Hansen, MC; McGrath-Horn, M; Carvalho, O; Hess, L | C59: Slowing Amazon deforestation through public policy and interventions in beef and soy supply chains | D59: SCIENCE | E59: Review | F59: The recent 70% decline in deforestation in the Brazilian Amazon suggests that it is possible to manage the advance of a vast agricultural frontier. Enforcement of laws, interventions in soy and beef supply chains, restrictions on access to credit, and expansion of protected areas appear to have contributed to this decline, as did a decline in the demand for new deforestation. The supply chain interventions that fed into this deceleration are precariously dependent on corporate risk management, and public policies have relied excessively on punitive measures. Systems for delivering positive incentives for farmers to forgo deforestation have been designed but not fully implemented. Territorial approaches to deforestation have been effective and could consolidate progress in slowing deforestation while providing a framework for addressing other important dimensions of sustainable development. | G59: 10.1126/science.1248525 | H59: http://dx.doi.org/10.1126/science.1248525 | I59: Multidisciplinary Sciences | J59: 45982 | K59: WOS:000336791200038 | L59: View Full Record in Web of Science
A60: J | B60: Franzke, CLE | C60: WARMING TRENDS Nonlinear climate change | D60: NATURE CLIMATE CHANGE | E60: Editorial Material | G60: 10.1038/nclimate2245 | H60: http://dx.doi.org/10.1038/nclimate2245 | I60: Environmental Sciences; Environmental Studies; Meteorology & Atmospheric Sciences | J60: 45982 | K60: WOS:000337138700011 | L60: View Full Record in Web of Science
A61: J | B61: Moschet, C; Wittmer, I; Simovic, J; Junghans, M; Piazzoli, A; Singer, H; Stamm, C; Leu, C; Hollender, J | C61: How a Complete Pesticide Screening Changes the Assessment of Surface Water Quality | D61: ENVIRONMENTAL SCIENCE & TECHNOLOGY | E61: Article | F61: A comprehensive assessment of pesticides in surface waters is challenging due to the large number of potential contaminants. Most scientific studies and routine monitoring programs include only 15-40 pesticides, which leads to error-prone interpretations. In the present study, an extensive analytical screening was carried out using liquid chromatography-high-resolution mass spectrometry, covering 86% of all polar organic pesticides sold in Switzerland and applied to agricultural or urban land (in total 249 compounds), plus 134 transformation products; each of which could be quantified in the low ng/L range. Five medium-sized rivers, containing large areas of diverse crops and urban settlements within the respective catchments, were sampled between March and July 2012. More than 100 parent compounds and 40 transformation products were detected in total, between 30 and compounds in each two-week composite sample in concentrations up to 1500 ng/L. The sum of pesticide concentrations was above 1000 ng/L in 78% of samples. The chronic environmental quality standard was exceeded for 19 single substances; using a mixture toxicity approach, exceedances occurred over the whole measurement period in all rivers. With scenario calculations including only 30-40 frequently measured pesticides, the number of detected substances and the mixture toxicity would be underestimated on average by a factor of 2. Thus, selecting a subset of substances to assess the surface water quality may be sufficient, but a comprehensive screening yields substantially more confidence. | G61: 10.1021/es500371t | H61: http://dx.doi.org/10.1021/es500371t | I61: Engineering, Environmental; Environmental Sciences | J61: 45982 | K61: WOS:000336415200011 | L61: View Full Record in Web of Science
A62: J | B62: Haddeland, I; Heinke, J; Biemans, H; Eisner, S; Flörke, M; Hanasaki, N; Konzmann, M; Ludwig, F; Masaki, Y; Schewe, J; Stacke, T; Tessler, ZD; Wada, Y; Wisser, D | C62: Global water resources affected by human interventions and climate change | D62: PROCEEDINGS OF THE NATIONAL ACADEMY OF SCIENCES OF THE UNITED STATES OF AMERICA | E62: Article | F62: Humans directly change the dynamics of the water cycle through dams constructed for water storage, and through water withdrawals for industrial, agricultural, or domestic purposes. Climate change is expected to additionally affect water supply and demand. Here, analyses of climate change and direct human impacts on the terrestrial water cycle are presented and compared using a multimodel approach. Seven global hydrological models have been forced with multiple climate projections, and with and without taking into account impacts of human interventions such as dams and water withdrawals on the hydrological cycle. Model results are analyzed for different levels of global warming, allowing for analyses in line with temperature targets for climate change mitigation. The results indicate that direct human impacts on the water cycle in some regions, e. g., parts of Asia and in the western United States, are of the same order of magnitude, or even exceed impacts to be expected for moderate levels of global warming (+2 K). Despite some spread in model projections, irrigation water consumption is generally projected to increase with higher global mean temperatures. Irrigation water scarcity is particularly large in parts of southern and eastern Asia, and is expected to become even larger in the future. | G62: 10.1073/pnas.1222475110 | H62: http://dx.doi.org/10.1073/pnas.1222475110 | I62: Multidisciplinary Sciences | J62: 45982 | K62: WOS:000332560300026 | L62: View Full Record in Web of Science
A63: J | B63: Cazenave, A; Le Cozannet, G | C63: Sea level rise and its coastal impacts | D63: EARTHS FUTURE | E63: Review | F63: Global warming in response to accumulation of human-induced greenhouse gases inside the atmosphere has already caused several visible consequences, among them increase of the Earth's mean temperature and ocean heat content, melting of glaciers, and loss of ice from the Greenland and Antarctica ice sheets. Ocean warming and land ice melt in turn are causing sea level to rise. Sea level rise and its impacts on coastal zones have become a question of growing interest in the scientific community, as well as in the media and public. In this review paper, we summarize the most up-to-date knowledge about sea level rise and its causes, highlighting the regional variability that superimposes the global mean rise. We also present sea level projections for the 21st century under different warming scenarios. We next address the issue of the sea level rise impacts. We question whether there is already observational evidence of coastal impacts of sea level rise and highlight the fact that results differ from one location to another. This suggests that the response of coastal systems to sea level rise is highly dependent on local natural and human settings. We finally show that in spite of remaining uncertainties about future sea levels and related impacts, it becomes possible to provide preliminary assessment of regional impacts of sea level rise. | G63: 10.1002/2013EF000188 | H63: http://dx.doi.org/10.1002/2013EF000188 | I63: Environmental Sciences; Geosciences, Multidisciplinary; Meteorology & Atmospheric Sciences | J63: 45982 | K63: WOS:000358125500001 | L63: View Full Record in Web of Science
A64: J | B64: Rickson, RJ | C64: Can control of soil erosion mitigate water pollution by sediments? | D64: SCIENCE OF THE TOTAL ENVIRONMENT | E64: Article | F64: The detrimental impact of sediment and associated pollutants on water quality is widely acknowledged, with many watercourses in the UK failing to meet the standard of 'good ecological status'. Catchment sediment budgets show that hill slope erosion processes can be significant sources of waterborne sediment, with rates of erosion likely to increase given predicted future weather patterns. However, linking on-site erosion rates with off-site impacts is complicated because of the limited data on soil erosion rates in the UK and the dynamic nature of the source pathway receptor continuum over space and time. Even so, soil erosion control measures are designed to reduce sediment production (source) and mobilisation/transport (pathway) on hill slopes, with consequent mitigation of pollution incidents in watercourses (receptors). The purpose of this paper is to review the scientific evidence of the effectiveness of erosion control measures used in the UK to reduce sediment loads of hill slope origin in watercourses. Although over 73 soil erosion mitigation measures have been identified from the literature, empirical data on erosion control effectiveness are limited. Baseline comparisons for the 18 measures where data do exist reveal erosion control effectiveness is highly variable over time and between study locations. Given the limitations of the evidence base in terms of geographical coverage and duration of monitoring, performance of the different measures cannot be extrapolated to other areas. This uncertainty in effectiveness has implications for implementing erosion/sediment risk reduction policies, where quantified targets are stipulated, as is the case in the EU Freshwater Fish and draft Soil Framework Directives. Also, demonstrating technical effectiveness of erosion control measures alone will not encourage uptake by land managers: quantifying the costs and benefits of adopting erosion mitigation is equally important, but these are uncertain and difficult to express in monetary terms. (C) 2013 Elsevier B.V. All rights reserved. | G64: 10.1016/j.scitotenv.2013.05.057 | H64: http://dx.doi.org/10.1016/j.scitotenv.2013.05.057 | I64: Environmental Sciences | J64: 45982 | K64: WOS:000331776000125 | L64: View Full Record in Web of Science
A65: J | B65: Gypens, N; Borges, AV | C65: Increase in dimethylsulfide (DMS) emissions due to eutrophication of coastal waters offsets their reduction due to ocean acidification | D65: FRONTIERS IN MARINE SCIENCE | E65: Article | F65: Available information from manipulative experiments suggested that the emission of dimethylsulfide (DMS) would decrease in response to the accumulation of anthropogenic CO2 in the ocean (ocean acidification). However, in coastal environments, the carbonate chemistry of surface waters was also strongly modified by eutrophication and related changes in biological activity (increased primary production and change in phytoplankton dominance) during the last 50 years. Here, we tested the hypothesis that DMS emissions in marine coastal environments also strongly responded to eutrophication in addition to ocean acidification at decadal timescales. We used the R-MIRO-BIOGAS model in the eutrophied Southern Bight of the North Sea characterized by intense blooms of Phaeocystis that are high producers of dimethylsulfoniopropionate (DMSP), the precursor of DMS. We showed that, for the period from 1951 to 2007, eutrophication actually led to an increase of DMS emissions much stronger than the response of DMS emissions to ocean acidification. | G65: 10.3389/fmars.2014.00004 | H65: http://dx.doi.org/10.3389/fmars.2014.00004 | I65: Environmental Sciences; Marine & Freshwater Biology | J65: 45982 | K65: WOS:000485310600004 | L65: View Full Record in Web of Science
A66: J | B66: Kanemoto, K; Moran, D; Lenzen, M; Geschke, A | C66: International trade undermines national emission reduction targets: New evidence from air pollution | D66: GLOBAL ENVIRONMENTAL CHANGE-HUMAN AND POLICY DIMENSIONS | E66: Article | F66: Many developed countries in Annex B of the Kyoto Protocol have been able to report decreasing emissions, and some have officially fulfilled their CO2 reduction commitments. This is in part because current reporting and regulatory regimes allow these countries to displace emissions intensive production offshore. Using a new highly detailed account of emissions embodied in international trade we investigate this phenomenon of emissions leakage. We independently confirm previous findings that adjusting for trade, developed countries emissions have increased, not decreased. We find that the sectors successfully holding or lowering their domestic emissions are often the same as those increasing their imports of embodied CO2. We also find that the fastest growing flow paths of embodied CO2 largely originate outside the Kyoto Annex B signatory nations. Finally, we find that historically the same phenomenon of emissions displacement has already occurred for air pollution, with the result that despite aggressive legislation in major emitters total global air pollution emissions have increased. If regulatory policies do not account for embodied imports, global emissions are likely to rise even if developed countries emitters enforce strong national emissions targets. (C) 2013 Elsevier Ltd. All rights reserved. | G66: 10.1016/j.gloenvcha.2013.09.008 | H66: http://dx.doi.org/10.1016/j.gloenvcha.2013.09.008 | I66: Environmental Sciences; Environmental Studies; Geography | J66: 45982 | K66: WOS:000333506100007 | L66: View Full Record in Web of Science
A67: J | B67: Sato, T; Qadir, M; Yamamoto, S; Endo, T; Zahoor, A | C67: Global, regional, and country level need for data on wastewater generation, treatment, and use | D67: AGRICULTURAL WATER MANAGEMENT | E67: Review | F67: Irrigation with wastewater supports agricultural production and the livelihoods of millions of smallholder farmers in many parts of the world. Considering the importance of better wastewater management at the local and national levels, there is a need for updated national data on wastewater generation, treatment, and use, which would also assist in regional and global wastewater assessments. While searching data and literature in published or electronic forms for 181 countries, we find that only 55 countries have data available on all three aspects of wastewater - generation, treatment, and use. The number of countries with one or two aspects of wastewater generation, treatment, and use is 69, while there is no information available from 57 countries. Of the available information, only 37% of the data could be categorized as recent (reported during 2008-2012). The available data suggest that high-income countries on average treat 70% of the generated wastewater, followed by upper-middle-income countries (38%), lower-middle-income countries (28%), and low-income countries, where only 8% of the wastewater generated is treated. The availability of current information on wastewater generation, treatment, and use is crucially important for policy makers, researchers, and practitioners, as well as public institutions, to develop national and local action plans aiming at safe and productive use of wastewater in agriculture, aquaculture, and agroforestry systems. The country level information aggregated at the regional and global levels would help in identifying the gaps in pertinent data availability and assessing the potential of wastewater in food, feed, and fish production at different scales. (C) 2013 Elsevier B.V. All rights reserved. | G67: 10.1016/j.agwat.2013.08.007 | H67: http://dx.doi.org/10.1016/j.agwat.2013.08.007 | I67: Agronomy; Water Resources | J67: 45982 | K67: WOS:000326559900001 | L67: View Full Record in Web of Science
A68: J | B68: Six, KD; Kloster, S; Ilyina, T; Archer, SD; Zhang, K; Maier-Reimer, E | C68: Global warming amplified by reduced sulphur fluxes as a result of ocean acidification | D68: NATURE CLIMATE CHANGE | E68: Article | F68: Climate change and decreasing seawater pH (ocean acidification)(1) have widely been considered as uncoupled consequences of the anthropogenic CO2 perturbation(2,3). Recently, experiments in seawater enclosures (mesocosms) showed that concentrations of dimethylsulphide (DMS), a biogenic sulphur compound, were markedly lower in a low-pH (e)nvironment4. Marine DMS emissions are the largest natural source of atmospheric sulphur(5) and changes in their strength have the potential to alter the Earth's radiation budget(6). Here we establish observational-based relationships between pH changes and DMS concentrations to estimate changes in future DMS emissions with Earth system model(7) climate simulations. Global DMS emissions decrease by about 18(+/-3)% in 2100 compared with pre-industrial times as a result of the combined effects of ocean acidification and climate change. The reduced DMS emissions induce a significant additional radiative forcing, of which 83% is attributed to the impact of ocean acidification, tantamount to an equilibrium temperature response between 0.23 and 0.48 K. Our results indicate that ocean acidification has the potential to exacerbate anthropogenic warming through a mechanism that is not considered at present in projections of future climate change. | G68: 10.1038/NCLIMATE1981 | H68: http://dx.doi.org/10.1038/NCLIMATE1981 | I68: Environmental Sciences; Environmental Studies; Meteorology & Atmospheric Sciences | J68: 45982 | K68: WOS:000330125100016 | L68: View Full Record in Web of Science
A69: J | B69: Hoornweg, D; Bhada-Tata, P; Kennedy, C | C69: Waste production must peak this century | D69: NATURE | E69: Editorial Material | G69: 10.1038/502615a | H69: http://dx.doi.org/10.1038/502615a | I69: Multidisciplinary Sciences | J69: 45982 | K69: WOS:000326293200021 | L69: View Full Record in Web of Science
A70: J | B70: Meyfroidt, P; Lambin, EF; Erb, KH; Hertel, TW | C70: Globalization of land use: distant drivers of land change and geographic displacement of land use | D70: CURRENT OPINION IN ENVIRONMENTAL SUSTAINABILITY | E70: Review | F70: Several streams of research have recently converged to identify the growing importance of distant drivers of land change, interconnections between social-ecological systems that are separated geographically, and the indirect consequences of land use changes. Local to national-scale interventions to promote sustainable land use may have unintended effects owing to a displacement of land use within and across countries. Such leakage or 'indirect land use change' critically depends on international geographies of trade. Computing various material flows and environmental indicators embodied in international trade highlights the differences between producer and consumer-based biophysical accounting. Causal attribution of the links between material and monetary flows across countries, and actual land changes and environmental impacts at local level requires a combination of economic simulation models, statistical studies, place-based empirical studies, value chain analyses, and biophysical accounting. | G70: 10.1016/j.cosust.2013.04.003 | H70: http://dx.doi.org/10.1016/j.cosust.2013.04.003 | I70: Green & Sustainable Science & Technology; Environmental Sciences | J70: 45982 | K70: WOS:000325843700002 | L70: View Full Record in Web of Science
A71: J | B71: Beketov, MA; Kefford, BJ; Schäfer, RB; Liess, M | C71: Pesticides reduce regional biodiversity of stream invertebrates | D71: PROCEEDINGS OF THE NATIONAL ACADEMY OF SCIENCES OF THE UNITED STATES OF AMERICA | E71: Article | F71: The biodiversity crisis is one of the greatest challenges facing humanity, but our understanding of the drivers remains limited. Thus, after decades of studies and regulation efforts, it remains unknown whether to what degree and at what concentrations modern agricultural pesticides cause regional-scale species losses. We analyzed the effects of pesticides on the regional taxa richness of stream invertebrates in Europe (Germany and France) and Australia (southern Victoria). Pesticides caused statistically significant effects on both the species and family richness in both regions, with losses in taxa up to 42% of the recorded taxonomic pools. Furthermore, the effects in Europe were detected at concentrations that current legislation considers environmentally protective. Thus, the current ecological risk assessment of pesticides falls short of protecting biodiversity, and new approaches linking ecology and ecotoxicology are needed. | G71: 10.1073/pnas.1305618110 | H71: http://dx.doi.org/10.1073/pnas.1305618110 | I71: Multidisciplinary Sciences | J71: 45982 | K71: WOS:000321978000046 | L71: View Full Record in Web of Science
A72: J | B72: Krausmann, F; Erb, KH; Gingrich, S; Haberl, H; Bondeau, A; Gaube, V; Lauk, C; Plutzar, C; Searchinger, TD | C72: Global human appropriation of net primary production doubled in the 20th century | D72: PROCEEDINGS OF THE NATIONAL ACADEMY OF SCIENCES OF THE UNITED STATES OF AMERICA | E72: Article | F72: Global increases in population, consumption, and gross domestic product raise concerns about the sustainability of the current and future use of natural resources. The human appropriation of net primary production (HANPP) provides a useful measure of human intervention into the biosphere. The productive capacity of land is appropriated by harvesting or burning biomass and by converting natural ecosystems to managed lands with lower productivity. This work analyzes trends in HANPP from 1910 to 2005 and finds that although human population has grown fourfold and economic output 17-fold, global HANPP has only doubled. Despite this increase in efficiency, HANPP has still risen from 6.9 Gt of carbon per y in 1910 to 14.8 GtC/y in 2005, i.e., from 13% to 25% of the net primary production of potential vegetation. Biomass harvested per capita and year has slightly declined despite growth in consumption because of a decline in reliance on bioenergy and higher conversion efficiencies of primary biomass to products. The rise in efficiency is overwhelmingly due to increased crop yields, albeit frequently associated with substantial ecological costs, such as fossil energy inputs, soil degradation, and biodiversity loss. If humans can maintain the past trend lines in efficiency gains, we estimate that HANPP might only grow to 27-29% by 2050, but providing large amounts of bioenergy could increase global HANPP to 44%. This result calls for caution in refocusing the energy economy on land-based resources and for strategies that foster the continuation of increases in land-use efficiency without excessively increasing ecological costs of intensification. | G72: 10.1073/pnas.1211349110 | H72: http://dx.doi.org/10.1073/pnas.1211349110 | I72: Multidisciplinary Sciences | J72: 45982 | K72: WOS:000321500200066 | L72: View Full Record in Web of Science
A73: J | B73: Van Dijk, TC; Van Staalduinen, MA; Van der Sluijs, JP | C73: Macro-Invertebrate Decline in Surface Water Polluted with Imidacloprid | D73: PLOS ONE | E73: Article | F73: Imidacloprid is one of the most widely used insecticides in the world. Its concentration in surface water exceeds the water quality norms in many parts of the Netherlands. Several studies have demonstrated harmful effects of this neonicotinoid to a wide range of non-target species. Therefore we expected that surface water pollution with imidacloprid would negatively impact aquatic ecosystems. Availability of extensive monitoring data on the abundance of aquatic macro-invertebrate species, and on imidacloprid concentrations in surface water in the Netherlands enabled us to test this hypothesis. Our regression analysis showed a significant negative relationship (P<0.001) between macro-invertebrate abundance and imidacloprid concentration for all species pooled. A significant negative relationship was also found for the orders Amphipoda, Basommatophora, Diptera, Ephemeroptera and Isopoda, and for several species separately. The order Odonata had a negative relationship very close to the significance threshold of 0.05 (P <0.051). However, in accordance with previous research, a positive relationship was found for the order Actinedida. We used the monitoring field data to test whether the existing three water quality norms for imidacloprid in the Netherlands are protective in real conditions. Our data show that macrofauna abundance drops sharply between 13 and 67 ng l(-1). For aquatic ecosystem protection, two of the norms are not protective at all while the strictest norm of 13 ng l(-1) (MTR) seems somewhat protective. In addition to the existing experimental evidence on the negative effects of imidacloprid on invertebrate life, our study, based on data from large-scale field monitoring during multiple years, shows that serious concern about the far-reaching consequences of the abundant use of imidacloprid for aquatic ecosystems is justified. | G73: 10.1371/journal.pone.0062374 | H73: http://dx.doi.org/10.1371/journal.pone.0062374 | I73: Multidisciplinary Sciences | J73: 45982 | K73: WOS:000319167000043 | L73: View Full Record in Web of Science
A74: J | B74: Chidumayo, EN; Gumbo, DJ | C74: The environmental impacts of charcoal production in tropical ecosystems of the world: A synthesis | D74: ENERGY FOR SUSTAINABLE DEVELOPMENT | E74: Review | F74: Charcoal production in tropical regions of the world is often perceived to have devastating ecological and environmental effects and governments, public forestry institutions and non government organizations have been particularly concerned about these charcoal-related impacts. The most commonly cited impact is deforestation, i.e., the clearance of forest or woodland. At a small spatial scale this may indeed be the case but on a larger landscape scale charcoal production most frequently results only in forest degradation. Much of the charcoal in tropical countries is commonly made in traditional earth and pit kilns with a wood-to-charcoal conversion rate of about 20% and in 2009 the contribution of charcoal production to deforestation in tropical countries with the highest rates of deforestation is estimated at less than 7%. A large proportion of the area utilized for charcoal production has the potential for rapid forest recovery especially with good post-harvest management. There are conflicting reports on the effects of deforestation on catchment hydrology with the majority of small catchment studies indicating increased runoff and low evapotranspiration while studies of large basins have shown no such changes. Emissions of greenhouse gases from charcoal production in tropical ecosystems in 2009 are estimated at 71.2 million t for carbon dioxide and 1.3 million t for methane. The failure of past charcoal policies to address environmental impacts and achieve sustainability can be attributed to erroneous assumptions and predictions by national and international organizations regarding wood-based fuels. Possible ways of enhancing charcoal policies' legitimacy and therefore effective implementation are multi-stakeholder participation and demonstration of coherence with globally recognized principles, goals and relevant international regimes, such as the Millennium Development Goals (MDGs). In this way charcoal production can significantly contribute to poverty reduction and environmental sustainability. (C) 2012 International Energy Initiative. Published by Elsevier Inc. All rights reserved. | G74: 10.1016/j.esd.2012.07.004 | H74: http://dx.doi.org/10.1016/j.esd.2012.07.004 | I74: Green & Sustainable Science & Technology; Energy & Fuels | J74: 45982 | K74: WOS:000317091400003 | L74: View Full Record in Web of Science
A75: J | B75: Ausubel, JH; Wernick, IK; Waggoner, PE | C75: Peak Farmland and the Prospect for Land Sparing | D75: POPULATION AND DEVELOPMENT REVIEW | E75: Article | G75: 10.1111/j.1728-4457.2013.00561.x | H75: http://dx.doi.org/10.1111/j.1728-4457.2013.00561.x | I75: Demography; Sociology | J75: 45982 | K75: WOS:000315224500015 | L75: View Full Record in Web of Science
