Workbook

Sheet Notes
B2: Ridley et al
B3: 10.1186/s13750-022-00279-7
B4: https://link.springer.com/article/10.1186/s13750-022-00279-7
B5: Raw - 1 | C5: Details of all 1069 records part of Ridley et al study
B6: Raw - 2 | C6: Result of data labelling done by authors for each document
B7: Enriched | C7: - Study_design - Column created based on author's "study_design" col; Adopt labels of Obs, Experimental, Review - realm - Based on ecoregoin column of author, create "realm" label which is essentially same. Only the col is renamed to be consistent with name and outputs are present in string list form.
B8: Curated - Labels | C8: Export of 933 WOS records and their labels of study design, realm, threat l1
B9: Ridely - Data Coding of Threats | C9: - Threats were classified according to the IUCN Red List threat classification scheme - Precision: L1 -> L3 (Lowest to highest) e.g. level 1 = Biological Resource Use & Level 2 = Hunting and Collecting Terrestrial Animals here threat precision is 2. - Precision studies below L2 & NOT "not captured by the IUCN criteria" coded as level 1 + unspecified - Precision = Other - threat satisfied the definition of threats used here but wasn’t covered by the IUCN classification This file filter: - Remove "unspec" coded rows - Remove "other" unspec rowsx - Remove cumulative precsion in serving lables

Sheet Raw - 1
A1: ArticleID | B1: Pub_Type | C1: Authors | D1: Year | E1: Title | F1: Pub_name | G1: Volume | H1: Issue | I1: Pages | J1: source | K1: "
A2: 23583 | B2: Journal Article | C2: Coll_etal | D2: 2015 | E2: 'Low-hanging fruit' for conservation of marine vertebrate species at risk in the Mediterranean Sea | F2: Global Ecology and Biogeography | G2: 24 | H2: 2 | I2: 226-239 | J2: PubDatabase
A3: 24558 | B3: Journal Article | C3: Lieske_etal | D3: 2020 | E3: “Seas of risk”: Assessing the threats to colonial-nesting seabirds in Eastern Canada | F3: Marine Policy | G3: 115 | H3: NA | I3: NA | J3: PubDatabase
A4: 25889 | B4: Journal Article | C4: Vasilakis_etal | D4: 2017 | E4: A balanced solution to the cumulative threat of industrialized wind farm development on cinereous vultures (Aegypius monachus) in south-eastern Europe | F4: PLoS ONE | G4: 12 | H4: 2 | I4: NA | J4: PubDatabase
A5: 25688 | B5: Journal Article | C5: Stoica_etal | D5: 2017 | E5: A case study in the Moldavian Central Plateau, Romania - habitat distribution, conservation status and human impact in a protected area | F5: Contributii Botanice | G5: 52 | H5: NA | I5: 119-131 | J5: PubDatabase
A6: 23785 | B6: Report | C6: Duran, M., Murillo, F. J., Serrano, A., Sayago-Gil, M., Parra, S., Diaz del, R., Sacau, M., Patrocinio, T. and Cristobo, J. | D6: 2008 | E6: A Case Study of available methodology for the identification of Vulnerable Ecosystems/Habitats in bottom deep-sea fisheries: Possibilities to apply this method in the NAFO Regulatory Area in order to select Marine Protected Areas | F6: NA | G6: NA | H6: NA | I6: NA | J6: PubDatabase
A7: 23461 | B7: Journal Article | C7: Caro_etal | D7: 2020 | E7: A case study of the coconut crab Birgus latro on Zanzibar highlights global threats and conservation solutions | F7: ORYX | G7: NA | H7: NA | I7: NA | J7: PubDatabase
A8: 25299 | B8: Journal Article | C8: Rasmussen_etal | D8: 2013 | E8: A catchment scale evaluation of multiple stressor effects in headwater streams | F8: Science of the Total Environment | G8: 442 | H8: NA | I8: 420-431 | J8: PubDatabase
A9: 24656 | B9: Journal Article | C9: Magness_etal | D9: 2011 | E9: A climate-change adaptation framework to reduce continental-scale vulnerability across conservation reserves | F9: Ecosphere | G9: 2 | H9: 10 | I9: 23 | J9: PubDatabase
A10: 23573 | B10: Journal Article | C10: Clay_etal | D10: 2019 | E10: A comprehensive large-scale assessment of fisheries bycatch risk to threatened seabird populations | F10: Journal of Applied Ecology | G10: 56 | H10: 8 | I10: 1882-1893 | J10: PubDatabase
A11: 23151 | B11: Journal Article | C11: Asner_etal | D11: 2009 | E11: A contemporary assessment of change in humid tropical forests | F11: Conservation Biology | G11: 23 | H11: 6 | I11: 1386-1395 | J11: PubDatabase
A12: 26057 | B12: Journal Article | C12: Wraith and Pickering | D12: 2019 | E12: A continental scale analysis of threats to orchids | F12: Biological Conservation | G12: 234 | H12: NA | I12: 42917 | J12: PubDatabase
A13: 25664 | B13: Journal Article | C13: Stafford_etal | D13: 2017 | E13: A Cross-Site Analysis of Neotropical Bird Hunting Profiles | F13: Tropical Conservation Science | G13: 10 | H13: NA | I13: NA | J13: PubDatabase
A14: 24696 | B14: Journal Article | C14: Marotta_etal | D14: 2011 | E14: A decision-support system in ICZM for protecting the ecosystems: Integration with the habitat directive | F14: Journal of Coastal Conservation | G14: 15 | H14: 3 | I14: 393-405 | J14: PubDatabase
A15: 25692 | B15: Journal Article | C15: Stortini_etal | D15: 2015 | E15: A decision-support tool to facilitate discussion of no-take boundaries for Marine Protected Areas during stakeholder consultation processes | F15: Journal for Nature Conservation | G15: 23 | H15: NA | I15: 45-52 | J15: PubDatabase
A16: 23868 | B16: Journal Article | C16: Fasola and Roesler | D16: 2018 | E16: A familiar face with a novel behavior raises challenges for conservation: American mink in arid Patagonia and a critically endangered bird | F16: Biological Conservation | G16: 218 | H16: NA | I16: 217-222 | J16: PubDatabase
A17: 25629 | B17: Journal Article | C17: Smolinski and Calkiewicz | D17: 2015 | E17: A fish-based index for assessing the ecological status of Polish transitional and coastal waters | F17: Marine Pollution Bulletin | G17: 101 | H17: 2 | I17: 497-506 | J17: PubDatabase
A18: 25026 | B18: Journal Article | C18: Ondei_etal | D18: 2019 | E18: A flexible tool to prioritize areas for conservation combining landscape units, measures of biodiversity, and threats | F18: Ecosphere | G18: 10 | H18: 9 | I18: NA | J18: PubDatabase
A19: 24868 | B19: Journal Article | C19: Morelli_etal | D19: 2020 | E19: A forecasting map of avian roadkill-risk in Europe: A tool to identify potential hotspots | F19: Biological Conservation | G19: 249 | H19: NA | I19: NA | J19: PubDatabase
A20: 24428 | B20: Journal Article | C20: Kostoski_etal | D20: 2010 | E20: A freshwater biodiversity hotspot under pressure - Assessing threats and identifying conservation needs for ancient Lake Ohrid | F20: Biogeosciences | G20: 7 | H20: 12 | I20: 3999-4015 | J20: PubDatabase
A21: 24242 | B21: Journal Article | C21: Howard_etal | D21: 2018 | E21: A freshwater conservation blueprint for California: Prioritizing watersheds for freshwater biodiversity | F21: Freshwater Science | G21: 37 | H21: 2 | I21: 417-431 | J21: PubDatabase
A22: 25381 | B22: Journal Article | C22: Robertson_etal | D22: 2004 | E22: A fuzzy classification technique for predicting species' distributions: Applications using invasive alien plants and indigenous insects | F22: Diversity and Distributions | G22: 10 | H22: 44717 | I22: 461-474 | J22: PubDatabase
A23: 25371 | B23: Journal Article | C23: Riolo | D23: 2006 | E23: A geographic information system for fisheries management in American Samoa | F23: Environmental Modelling and Software | G23: 21 | H23: 7 | I23: 1025-1041 | J23: PubDatabase
A24: 26032 | B24: Journal Article | C24: Winchell_etal | D24: 2012 | E24: A GIS-based approach to quantifying pesticide use site proximity to salmonid habitat | F24: ACS Symposium Series | G24: 1111 | H24: NA | I24: 183-196 | J24: PubDatabase
A25: 25078 | B25: Journal Article | C25: Pasqualini_etal | D25: 2011 | E25: A GIS-based multicriteria evaluation for aiding risk management Pinus pinaster Ait. Forests: A case study in Corsican island, western Mediterranean region | F25: Environmental Management | G25: 48 | H25: 1 | I25: 38-56 | J25: PubDatabase
A26: 23163 | B26: Journal Article | C26: Aubrecht_etal | D26: 2008 | E26: A global inventory of coral reef stressors based on satellite observed nighttime lights | F26: Geocarto International | G26: 23 | H26: 6 | I26: 467-479 | J26: PubDatabase
A27: 24125 | B27: Journal Article | C27: Halpern_etal | D27: 2008 | E27: A global map of human impact on marine ecosystems | F27: Science | G27: 319 | H27: 5865 | I27: 948-952 | J27: PubDatabase
A28: 24525 | B28: Journal Article | C28: Lewis_etal | D28: 2020 | E28: A Global Perspective on Firefly Extinction Threats | F28: BioScience | G28: 70 | H28: 2 | I28: 157-167 | J28: PubDatabase
A29: 24078 | B29: Journal Article | C29: Graham_etal | D29: 2016 | E29: A Global-Scale Evaluation of Primate Exposure and Vulnerability to Climate Change | F29: International Journal of Primatology | G29: 37 | H29: 2 | I29: 158-174 | J29: PubDatabase
A30: 25033 | B30: Journal Article | C30: Orgiazzi_etal | D30: 2016 | E30: A knowledge-based approach to estimating the magnitude and spatial patterns of potential threats to soil biodiversity | F30: Science of the Total Environment | G30: 545-546 | H30: NA | I30: 44136 | J30: PubDatabase
A31: 26042 | B31: Journal Article | C31: Winters_etal | D31: 2017 | E31: A low cost field-survey method for mapping seagrasses and their potential threats: an example from the northern Gulf of Aqaba, Red Sea | F31: Aquatic Conservation: Marine and Freshwater Ecosystems | G31: 27 | H31: 2 | I31: 324-339 | J31: PubDatabase
A32: 25158 | B32: Journal Article | C32: Pilcher_etal | D32: 2017 | E32: A low-cost solution for documenting distribution and abundance of endangered marine fauna and impacts from fisheries | F32: PLoS ONE | G32: 12 | H32: 12 | I32: NA | J32: PubDatabase
A33: 25529 | B33: Journal Article | C33: Selkoe_etal | D33: 2009 | E33: A map of human impacts to a "pristine" coral reef ecosystem, the Papah?naumoku?kea Marine National Monument | F33: Coral Reefs | G33: 28 | H33: 3 | I33: 635-650 | J33: PubDatabase
A34: 24659 | B34: Journal Article | C34: Magris_etal | D34: 2019 | E34: A modelling approach to assess the impact of land mining on marine biodiversity: Assessment in coastal catchments experiencing catastrophic events (SW Brazil) | F34: Science of the Total Environment | G34: 659 | H34: NA | I34: 828-840 | J34: PubDatabase
A35: 24777 | B35: Journal Article | C35: Menegon_etal | D35: 2018 | E35: A modelling framework for MSP-oriented cumulative effects assessment | F35: Ecological Indicators | G35: 91 | H35: NA | I35: 171-181 | J35: PubDatabase
A36: 23685 | B36: Journal Article | C36: De_etal | D36: 2020 | E36: A multiscale analysis of land use dynamics in the buffer zone of Rio Doce State Park, Minas Gerais, Brazil | F36: Journal of Environmental Planning and Management | G36: 63 | H36: 5 | I36: 935-957 | J36: PubDatabase
A37: 23086 | B37: Journal Article | C37: Alvarez-Romero_etal | D37: 2013 | E37: A novel approach to model exposure of coastal-marine ecosystems to riverine flood plumes based on remote sensing techniques | F37: Journal of Environmental Management | G37: 119 | H37: NA | I37: 194-207 | J37: PubDatabase
A38: 25234 | B38: Journal Article | C38: Pusparini_etal | D38: 2018 | E38: A pathway to recovery: The Critically Endangered Sumatran tiger Panthera tigris sumatrae in an 'in danger' UNESCO World Heritage Site | F38: ORYX | G38: 52 | H38: 1 | I38: 25-34 | J38: PubDatabase
A39: 24229 | B39: Journal Article | C39: Holon_etal | D39: 2018 | E39: A predictive model based on multiple coastal anthropogenic pressures explains the degradation status of a marine ecosystem: Implications for management and conservation | F39: Biological Conservation | G39: 222 | H39: NA | I39: 125-135 | J39: PubDatabase
A40: 24636 | B40: Journal Article | C40: Macdonald_etal | D40: 2013 | E40: A problem shared is a problem reduced: Seeking efficiency in the conservation of felids and primates | F40: Folia Primatologica | G40: 83 | H40: 44715 | I40: 171-215 | J40: PubDatabase
...

Sheet Raw - 2
A1: ArticleID | B1: Authors | C1: Year | D1: Study_design | E1: Ecoregion | F1: Spatial_Scale | G1: Spatial_res_unit | H1: Spatial_res | I1: Continent_Ocean | J1: Country_EEZ | K1: Threat_metric | L1: Threat_data | M1: Threat | N1: Quantity_threats | O1: threat_precision | P1: threat_database | Q1: Pop_metric | R1: Pop_data | S1: pop_database | T1: tax_res | U1: tax_scope | V1: tax_kingdom | W1: plant_group | X1: animal_group
A2: 25370 | B2: Rímalová_etal | C2: 2014 | D2: Observational | E2: Freshwater | F2: National | G2: polygon | H2: NA | I2: europe | J2: Czech Republic | K2: survey | L2: Qualitative | M2: 8.1:SDAlienInv | N2: 1 | O2: level2 | P2: NA | Q2: survey | R2: Qualitative | S2: NA | T2: species | U2: order | V2: animalia | W2: na | X2: invertebrates
A3: 23013 | B3: Abade_etal | C3: 2018 | D3: Observational | E3: Terrestrial | F3: Local | G3: polygon | H3: na | I3: africa | J3: Tanzania, United Republic of | K3: literature | L3: Qualitative | M3: 1.1:DevResid;2.3:AgLivestock;5.1:UseAnimals;6.3:Other | N3: 4 | O3: cumulative | P3: na | Q3: survey | R3: Quantitative | S3: na | T3: species | U3: species | V3: animalia | W3: na | X3: mammal
A4: 23018 | B4: Abrahms_etal | C4: 2019 | D4: Observational | E4: Marine | F4: Local | G4: degrees | H4: 0.1 | I4: north pacific | J4: United States | K4: database | L4: Qualitative | M4: 4.3:ShipLane | N4: 1 | O4: level2 | P4: Channel Islands National Marine Sanctuary | Q4: modelled | R4: Quantitative | S4: NA | T4: species | U4: species | V4: animalia | W4: na | X4: mammal
A5: 23019 | B5: Abram_etal | C5: 2015 | D5: Observational | E5: Terrestrial | F5: Local | G5: km2 | H5: 1 | I5: asia | J5: Indonesia | K5: expert | L5: Quantitative | M5: 6.3:Other | N5: 1 | O5: level2 | P5: na | Q5: expert | R5: Quantitative | S5: NA | T5: species | U5: species | V5: animalia | W5: na | X5: mammal
A6: 23020 | B6: Abreo_etal | C6: 2019 | D6: Observational | E6: Marine | F6: Sub-national | G6: polygon | H6: na | I6: south china sea | J6: Philippines | K6: other | L6: Quantitative | M6: 9.4:PollGarbSW | N6: 1 | O6: level2 | P6: na | Q6: other | R6: Qualitative | S6: NA | T6: species | U6: phylum | V6: animalia | W6: na | X6: mammal;reptile
A7: 23022 | B7: Acevedo_etal | C7: 2007 | D7: Observational | E7: Terrestrial | F7: Sub-national | G7: km2 | H7: 1 | I7: europe | J7: Spain | K7: survey | L7: Qualitative | M7: 2.3:AgLivestock | N7: 1 | O7: level2 | P7: na | Q7: modelled;survey | R7: Quantitative | S7: NA | T7: species | U7: species | V7: animalia | W7: na | X7: mammal
A8: 23030 | B8: Adams and Setterfield | C8: 2015 | D8: Observational | E8: Terrestrial | F8: Sub-national | G8: m | H8: 250 | I8: australasia | J8: Australia | K8: literature | L8: Qualitative | M8: 8.1:SDAlienInv | N8: 1 | O8: level2 | P8: na | Q8: pchba;protected_area | R8: Qualitative | S8: NRETAS | T8: other | U8: other | V8: other | W8: na | X8: na
A9: 23046 | B9: Ahmad_etal | C9: 2015 | D9: Observational | E9: Terrestrial | F9: Local | G9: polygon | H9: NA | I9: asia | J9: India | K9: rs | L9: Qualitative | M9: 2.1:AgNTC;2.3:AgLivestock;1.4:DevUnspec | N9: 3 | O9: level2 | P9: NA | Q9: protected_area | R9: Qualitative | S9: NA | T9: other | U9: other | V9: other | W9: na | X9: na
A10: 23047 | B10: Ahmadi_etal | C10: 2019 | D10: Observational | E10: Terrestrial | F10: Multi-national | G10: km2 | H10: 1 | I10: asia | J10: Azerbaijan;Iran;Lebanon;Turkey | K10: modelled | L10: Quantitative | M10: 11.1:CC_Habitat | N10: 2 | O10: level2 | P10: NA | Q10: literature;survey | R10: Qualitative | S10: NA | T10: genus | U10: genus | V10: animalia | W10: na | X10: reptile
A11: 23061 | B11: Albouy_etal | C11: 2017 | D11: Observational | E11: Marine | F11: Global | G11: degrees | H11: 1 | I11: na | J11: na | K11: pcm | L11: Qualitative | M11: 1.2:DevComInd;3.1:OilGas;4.3:ShipLane;5.4:UseAquatic;8.1:SDAlienInv;9.1:PollDWW;11.1:CC_Habitat;11.3:CC_Temp;11.5:CC_other | N11: 10 | O11: cumulative | P11: Halpern_2008 | Q11: database | R11: Quantitative | S11: IUCN | T11: order | U11: order | V11: animalia | W11: na | X11: mammal
A12: 23062 | B12: Albright_etal | C12: 2017 | D12: Observational | E12: Terrestrial | F12: Sub-national | G12: degrees | H12: 0.125 | I12: north america | J12: United States | K12: modelled | L12: Quantitative | M12: 11.2:CC_Drought | N12: 1 | O12: level2 | P12: NA | Q12: survey | R12: Qualitative | S12: NA | T12: species | U12: order | V12: animalia | W12: na | X12: bird
A13: 23063 | B13: Alcaraz_etal | C13: 2015 | D13: Observational | E13: Freshwater | F13: Sub-national | G13: km2 | H13: 10 | I13: europe | J13: Spain | K13: survey | L13: Qualitative | M13: 8.1:SDAlienInv | N13: 1 | O13: level2 | P13: NA | Q13: survey | R13: Qualitative | S13: NA | T13: species | U13: species | V13: animalia | W13: na | X13: Fish
A14: 23051 | B14: Al-Chokhachy_etal | C14: 2014 | D14: Observational | E14: Freshwater | F14: Local | G14: polygon | H14: NA | I14: north america | J14: Canada;United States | K14: survey | L14: Quantitative | M14: 8.2:SDNativProb | N14: 1 | O14: level2 | P14: NA | Q14: survey | R14: Qualitative | S14: NA | T14: species | U14: family | V14: animalia | W14: na | X14: Fish
A15: 23064 | B15: Alexander and Waters | C15: 2000 | D15: Observational | E15: Terrestrial | F15: Local | G15: polygon | H15: NA | I15: north america | J15: Canada | K15: survey | L15: Qualitative | M15: 4.1:RoadRail | N15: 1 | O15: level2 | P15: na | Q15: survey | R15: qualitative | S15: NA | T15: species | U15: class | V15: animalia | W15: na | X15: mammal
A16: 23068 | B16: Alfred_etal | C16: 2010 | D16: Observational | E16: Terrestrial | F16: Sub-national | G16: m | H16: 2.5 | I16: asia | J16: Malaysia | K16: rs | L16: Qualitative | M16: 2.1:AgNTC;2.2:AgWood;4.1:RoadRail | N16: 3 | O16: level2 | P16: NA | Q16: survey | R16: Quantitative | S16: NA | T16: species | U16: species | V16: animalia | W16: na | X16: mammal
A17: 23071 | B17: Allan_etal | C17: 2017 | D17: Observational | E17: Terrestrial | F17: Global | G17: polygon | H17: NA | I17: na | J17: na | K17: pcm | L17: Quantitative | M17: 1.1:DevResid;1.2:DevComInd;1.3:DevRnR;2.1:AgNTC;2.3:AgLivestock;4.1:RoadRail;9.6:PollEnergy | N17: 7 | O17: cumulative | P17: HFI | Q17: protected_area | R17: Qualitative | S17: NaturalWorldHeritage | T17: other | U17: other | V17: other | W17: na | X17: na
A18: 23072 | B18: Allan_etal | C18: 2019 | D18: Observational | E18: Terrestrial | F18: Global | G18: km2 | H18: 30 | I18: na | J18: na | K18: pcm | L18: Quantitative | M18: 1.1:DevResid;1.2:DevComInd;2.1:AgNTC;2.3:AgLivestock;4.1:RoadRail;4.2:UtilityLine;5.1:UseAnimals;5.2:UsePlant;6.1:ActivRnR;6.3:Other;8.1:SDAlienInv;9.1:PollDWW;9.3:PollAgrFor;9.4:PollGarbSW;9.6:PollEnergy | N18: 15 | O18: cumulative | P18: HFI | Q18: database | R18: Quantitative | S18: IUCN | T18: phylum | U18: phylum | V18: animalia | W18: na | X18: mammal;amphibia;bird
A19: 23073 | B19: Almeida_etal | C19: 2014 | D19: Observational | E19: Freshwater | F19: Sub-national | G19: km2 | H19: 10 | I19: europe | J19: United Kingdom | K19: survey | L19: Qualitative | M19: 8.1:SDAlienInv | N19: 1 | O19: level2 | P19: NA | Q19: survey | R19: Qualitative | S19: NA | T19: species | U19: species | V19: animalia | W19: na | X19: invertebrates
A20: 23074 | B20: Almodóvar_etal | C20: 2012 | D20: Observational | E20: Freshwater | F20: Local | G20: polygon | H20: NA | I20: europe | J20: Spain | K20: survey | L20: Qualitative | M20: 11.3:CC_Temp | N20: 1 | O20: level2 | P20: NA | Q20: survey | R20: Qualitative | S20: NA | T20: species | U20: species | V20: animalia | W20: na | X20: Fish
A21: 23052 | B21: Al-Nasrawi_etal | C21: 2018 | D21: Observational | E21: Terrestrial | F21: Local | G21: m | H21: 0.8 | I21: australasia | J21: Australia | K21: rs | L21: Qualitative | M21: 11.1:CC_Habitat | N21: 1 | O21: level2 | P21: NA | Q21: rs | R21: Qualitative | S21: NA | T21: phylum | U21: phylum | V21: plantae | W21: mangrove;vegetation | X21: na
A22: 23080 | B22: Álvarez | C22: 2003 | D22: Observational | E22: Terrestrial | F22: National | G22: polygon | H22: NA | I22: south america | J22: Colombia | K22: literature | L22: Qualitative | M22: 6.2:WarConflict | N22: 1 | O22: level2 | P22: NA | Q22: literature | R22: Qualitative | S22: NA | T22: kingdom | U22: kingdom | V22: plantae | W22: forest | X22: na
A23: 23082 | B23: Alvarez-Berastegui_etal | C23: 2014 | D23: Observational | E23: Marine | F23: Sub-national | G23: m | H23: 300 | I23: mediterranean | J23: Spain | K23: expert;literature;survey | L23: Quantitative | M23: 1.1:DevResid;2.4:Aqua;5.4:UseAquatic;6.1:ActivRnR | N23: 4 | O23: cumulative | P23: NA | Q23: expert;literature;survey | R23: Quantitative | S23: NA | T23: domain | U23: domain | V23: animalia;plantae | W23: liliopsida | X23: fish
A24: 23083 | B24: Alvarez-Berrios and Mitchell | C24: 2015 | D24: Observational | E24: Terrestrial | F24: Multi-national | G24: m | H24: 250 | I24: south america | J24: Brazil;Bolivia;Peru;French Guyana;Suriname;Guyana;Venezuela;Colombia;Ecuador | K24: database;literature;rs | L24: Qualitative | M24: 3.2:MinQuar | N24: 1 | O24: level2 | P24: private mining GIS databases | Q24: rs | R24: quantitative | S24: NA | T24: kingdom | U24: kingdom | V24: plantae | W24: forest | X24: na
A25: 23085 | B25: Alvarez-Filip_etal | C25: 2019 | D25: Observational | E25: Marine | F25: Sub-national | G25: polygon | H25: na | I25: north atlantic | J25: Mexico | K25: survey | L25: Quantitative | M25: 8.6:DUnknownC | N25: 1 | O25: level2 | P25: na | Q25: survey | R25: qualitative | S25: NA | T25: class | U25: class | V25: animalia | W25: na | X25: invertebrates
A26: 23086 | B26: Alvarez-Romero_etal | C26: 2013 | D26: Observational | E26: Marine | F26: Sub-national | G26: m | H26: 500 | I26: south pacific | J26: Australia | K26: modelled;rs | L26: Quantitative | M26: 9.7:PollUnspec | N26: 1 | O26: level1 | P26: NA | Q26: rs | R26: Qualitative | S26: NA | T26: family | U26: domain | V26: animalia;plantae | W26: liliopsida | X26: invertebrates
A27: 23087 | B27: Alves_etal | C27: 2014 | D27: Observational | E27: Terrestrial | F27: Multi-national | G27: degrees | H27: 0.16 | I27: north america | J27: Canada;United States | K27: literature | L27: Qualitative | M27: 8.1:SDAlienInv | N27: 1 | O27: level2 | P27: NA | Q27: literature | R27: Qualitative | S27: NA | T27: family | U27: family | V27: animalia | W27: na | X27: mammal
A28: 25335 | B28: Amano_etal | C28: 2020 | D28: Observational | E28: Terrestrial | F28: Global | G28: degrees | H28: 1 | I28: na | J28: na | K28: database | L28: Quantitative | M28: 11.3:CC_Temp;11.5:CC_other | N28: 2 | O28: level2 | P28: CRU TS v4.01 | Q28: database;survey | R28: Quantitative | S28: International Bird Census_ICW | T28: class | U28: class | V28: animalia | W28: na | X28: bird
A29: 23091 | B29: Ambastha_etal | C29: 2010 | D29: Observational | E29: Terrestrial | F29: Local | G29: m | H29: 250 | I29: asia | J29: India | K29: rs | L29: Qualitative | M29: 1.1:DevResid;2.4:Aqua;2.5:AgUncpec | N29: 3 | O29: level2 | P29: NA | Q29: protected_area;rs | R29: Qualitative | S29: NA | T29: family | U29: family | V29: plantae | W29: liliopsida | X29: na
A30: 23100 | B30: Andersen_etal | C30: 2020 | D30: Observational | E30: Marine | F30: National | G30: km2 | H30: 2 | I30: north atlantic | J30: Denmark | K30: modelled | L30: Quantitative | M30: 7.2:WaterSystem;11.3:CC_Temp;9.7:PollUnspec;9.4:PollGarbSW;9.6:PollEnergy;1.2:DevComInd;2.4:Aqua;6.2:WarConflict;8.1:SDAlienInv;3.1:OilGas;3.3:Renew;4.2:UtilityLine;9.2:PollIndMil;4.3:ShipLane;6.1:ActivRnR;5.4:UseAquatic | N30: 16 | O30: cumulative | P30: NA | Q30: modelled | R30: Quantitative | S30: NA | T30: domain | U30: domain | V30: animalia;plantae | W30: liliopsida | X30: chordata
A31: W26591 | B31: Anderson_etal | C31: 2017 | D31: Observational | E31: Marine | F31: Local | G31: polygon | H31: NA | I31: north atlantic | J31: Belize | K31: survey | L31: Quantitative | M31: 8.1:SDAlienInv | N31: 1 | O31: level2 | P31: NA | Q31: protected_area | R31: Qualitative | S31: NA | T31: other | U31: other | V31: other | W31: na | X31: na
A32: 23105 | B32: Andrade-Díaz_etal | C32: 2019 | D32: Observational | E32: Terrestrial | F32: Sub-national | G32: NA | H32: NA | I32: south america | J32: Argentina | K32: database | L32: Qualitative | M32: 2.1:AgNTC;2.2:AgWood | N32: 2 | O32: cumulative | P32: geoportal.idesa.gob.ar | Q32: modelled | R32: Quantitative | S32: NA | T32: order | U32: order | V32: animalia | W32: na | X32: reptile
A33: 23106 | B33: Andréfouët_etal | C33: 2015 | D33: Observational | E33: Marine | F33: Multi-national | G33: m | H33: 30 | I33: south pacific | J33: Cook Islands;French Polynesia | K33: database;rs | L33: Quantitative | M33: 11.3:CC_Temp | N33: 1 | O33: level2 | P33: AVHRR Pathfinder V4.1 | Q33: literature | R33: Qualitative | S33: NA | T33: kingdom | U33: kingdom | V33: animalia | W33: na | X33: invertebrates
A34: 23114 | B34: Anjos_etal | C34: 2018 | D34: Observational | E34: Terrestrial | F34: Continental | G34: km2 | H34: 6 | I34: south america | J34: na | K34: modelled | L34: Quantitative | M34: 11.1:CC_Habitat | N34: 1 | O34: level2 | P34: na | Q34: rs | R34: qualitative | S34: NA | T34: kingdom | U34: kingdom | V34: plantae | W34: forest;habitat;habitat | X34: na
A35: 23117 | B35: Ansari and Golabi | C35: 2019 | D35: Observational | E35: Terrestrial | F35: Local | G35: polygon | H35: NA | I35: asia | J35: Iran | K35: rs;survey | L35: Qualitative | M35: 1.1:DevResid;2.1:AgNTC;2.3:AgLivestock | N35: 3 | O35: level1 | P35: NA | Q35: survey | R35: Qualitative | S35: NA | T35: species | U35: species | V35: animalia | W35: na | X35: mammal
A36: 23128 | B36: Araújo and Wang | C36: 2015 | D36: Observational | E36: Freshwater | F36: Sub-national | G36: polygon | H36: NA | I36: south america | J36: Brazil | K36: literature;rs | L36: Qualitative | M36: 7.2:WaterSystem | N36: 1 | O36: level2 | P36: NA | Q36: literature | R36: Qualitative | S36: NA | T36: species | U36: family | V36: animalia | W36: na | X36: mammal
A37: 23125 | B37: Araújo_etal | C37: 2008 | D37: Observational | E37: Terrestrial | F37: Continental | G37: km2 | H37: 50 | I37: europe | J37: na | K37: database | L37: Quantitative | M37: 1.1:DevResid;1.2:DevComInd;2.1:AgNTC;2.3:AgLivestock | N37: 3 | O37: level2 | P37: Eurostat2000 | Q37: modelled | R37: Qualitative | S37: NA | T37: class | U37: domain | V37: animalia;plantae | W37: tracheophyta | X37: bird;mammal;reptile;amphibia
A38: 23135 | B38: Arkema_etal | C38: 2014 | D38: Observational | E38: Marine | F38: National | G38: m | H38: 500 | I38: north atlantic | J38: Belize | K38: expert;modelled | L38: Quantitative | M38: 1.1:DevResid;1.2:DevComInd;1.3:DevRnR;2.4:Aqua;3.1:OilGas;4.3:ShipLane;5.4:UseAquatic;9.3:PollAgrFor;3.2:MinQuar;6.1:ActivRnR | N38: 10 | O38: level2 | P38: NA | Q38: expert | R38: Qualitative | S38: NA | T38: class | U38: domain | V38: animalia;plantae | W38: mangrove;liliopsida | X38: invertebrates
A39: 23138 | B39: Armenteras_etal | C39: 2013 | D39: Observational | E39: Terrestrial | F39: Local | G39: polygon | H39: NA | I39: south america | J39: Colombia | K39: rs | L39: Qualitative | M39: 2.3:AgLivestock;7.1:FireSystem;2.1:AgNTC | N39: 3 | O39: level2 | P39: NA | Q39: rs | R39: Qualitative | S39: NA | T39: kingdom | U39: kingdom | V39: plantae | W39: forest | X39: na
A40: 23142 | B40: Arroyave_etal | C40: 2020 | D40: Observational | E40: Terrestrial | F40: National | G40: polygon | H40: NA | I40: south america | J40: Colombia | K40: literature | L40: Qualitative;Quantitative | M40: 5.1:UseAnimals;6.3:Other | N40: 2 | O40: level2 | P40: NA | Q40: literature | R40: Qualitative | S40: NA | T40: class | U40: class | V40: animalia | W40: na | X40: reptile
...

Sheet Raw - 3 (Typology)
A1: Typologies | C1: *Where multiple, use a semi-colon to delimit (applies to: 2.1; 2.4; 2.7; 2.8; 3.3; 3.4; 4.3;4.4)
A3: Field Code | B3: 1.1 | C3: 2.1 | D3: 2.2 | E3: 2.3 | F3: 3.1 | G3: 3.2 | H3: 3.3 | I3: 3.4 | J3: 3.5 | K3: 3.6 | L3: 3.7 | M3: 4.1 | N3: 4.2 | O3: 4.3 | P3: 4.4 | R3: 4.5 | S3: 4.6 | T3: 5.1 | U3: 5.2 | V3: 5.3 | W3: 5.4 | X3: 5.5 | Y3: 5.6 | Z3: 5.7 | AA3: 5.8 | AB3: 6
A4: Data Field | B4: Article_ID | C4: Date_Coded | D4: Coded_by | E4: Inclusion | F4: Study_design | G4: Ecoregion | H4: Spatial_scale | I4: Spatial_res_unit | J4: Spatial_res | K4: Continent_Ocean | L4: Country_EEZ | M4: Threat_metric | N4: Threat_data | O4: Threat_database | P4: Threat | R4: Quantity_threats | S4: threat_precision | T4: Pop_metric | U4: Pop_data | V4: Pop_database | W4: Tax.res | X4: Tax.scope | Y4: Taxa.kingdom | Z4: animal.group | AA4: plant.group | AB4: Comment
A5: Data Type | B5: text | C5: Date | D5: Text | E5: binary | F5: Text | G5: Text | H5: Text | I5: Text | J5: numeric | K5: text | L5: text | M5: text | N5: text | O5: text | P5: list | R5: numeric | S5: list | T5: list | U5: list | V5: list | W5: list | X5: list | Y5: list | Z5: text | AA5: text | AB5: text
A6: Info | B6: EPPI4 ID | C6: Removed after coding was consolidated between the two reviewers | I6: na applied if polygon | K6: na applied if global | L6: na applied if spatial scale > country | O6: name of data source | R6: Number of tier 2 threats (3.6) | V6: name of data source | Z6: class | AA6: class | AB6: Removed after consolidation
C7: The date that the coding was applied | D7: The reviewer that coded the article | E7: Marks any decisions made regarding inclusion after the full-text screening stage | F7: The nature of the investigation | G7: The ecoregion(s) that the threat map covers | H7: The spatial scales covered by threat maps within the study | I7: The resolution at which the distribution of threats was presented | J7: The units that the spatial resolution was given in | K7: The broad geographic region that the threat map covers. Oceans = marine, continents = terrestrial an freshwater | L7: The country or countries that threat maps within the article cover. | M7: The methods used to collect and present data on where threats occur | N7: The type of data used to represent where threats occur | P7: Categories of human-driven threat according to Salafsky(2008). | R7: The number of distinct threat categories (4.4) mapped in each study. | S7: The thematic precision of the presentation of threats. See extended definitions | T7: The method used to collect and present data on the presence of individuals of a wild species | U7: The type of data used to collect and present data on the presence of individuals of a wild species | W7: See extended definitions | X7: See extended definitions | Z7: See extended definitions | AA7: See extended definitions
A10: Entry values | C10: dd.mm.yy | D10: FR | E10: 1=include | F10: Experimental | G10: Terrestrial | H10: Global | I10: km2 | K10: Africa | L10: na | M10: PCM | N10: Quantitative | O10: e.g. HFI (human footprint index) | P10: 1.1:DevResid | Q10: Housing & urban area | R10: 1 to 42 | S10: cumulative | T10: database | U10: Quantitative | V10: e.g IUCN | W10: Domain | X10: Domain | Y10: Animalia
D11: EH | E11: 0=exclude | F11: Observational | G11: Freshwater | H11: Continental | I11: degrees | K11: Antarctica | L11: Aruba | M11: RS | N11: Qualitative | O11: na (if source type is not database) | P11: 1.2:DevComInd | Q11: Commercial & industrial areas | S11: level1 | T11: survey | U11: Qualitative | V11: na (if source type is not database) | W11: Kingdom | X11: Kingdom | Y11: Plantae
F12: S_Review | G12: Marine | H12: Multi-national | I12: na | K12: Europe | L12: Antigua and Barbuda | M12: database | P12: 1.3:DevRnR | Q12: Tourism & recreation areas | S12: level2 | T12: PCHBA | W12: Phylum | X12: Phylum | Y12: na
H13: National | I13: m | K13: North America | L13: Afghanistan | M13: literature | P13: 1.4:DevUnspec | Q13: Unspecified Residential & commercial development | T13: Protected_Area | W13: Class | X13: Class
H14: Sub-national | I14: ha | K14: South America | L14: Algeria | M14: Survey | P14: 2.1:AgNTC | Q14: Annual & perennial non-timber crops | T14: Expert | W14: Order | X14: Order
H15: Local | I15: minutes | K15: Asia | L15: Azerbaijan | M15: Modelled | P15: 2.2:AgWood | Q15: Wood & pulp plantations | T15: RS | W15: Family | X15: Family
I16: m2 | K16: Australasia | L16: Albania | M16: Expert | P16: 2.3:AgLivestock | Q16: Livestock farming & ranching | T16: Literature | W16: Genus | X16: Genus
I17: arc_seconds | K17: Arctic_Ocean | L17: Armenia | M17: Other | P17: 2.4:Aqua | Q17: Marine & freshwater aquaculture | T17: Other | W17: Species | X17: Species
I18: nm2 | K18: North_Atlantic_Ocean | L18: Andorra | P18: 2.5:AgUncpec | Q18: Unspecified Agriculture & aquaculture | T18: Modelled | W18: na | X18: na
K19: South_Atlantic_Ocean | L19: Angola | P19: 3.1:OilGas | Q19: Oil & gas drilling
K20: Indian_Ocean | L20: American Samoa | P20: 3.2:MinQuar | Q20: Mining & quarrying
K21: North_Pacific_Ocean | L21: Argentina | P21: 3.3:Renew | Q21: Renewable energy
K22: South_Pacific_Ocean | L22: Australia | P22: 3.4:EnergUnspec | Q22: Unspecified Energy production & mining
K23: Mediterannean | L23: Austria | P23: 4.1:RoadRail | Q23: Roads & railroads
K24: South China Sea | L24: Anguilla | P24: 4.2:UtilityLine | Q24: Utility & service lines
K25: CaspianSea | L25: Antarctica | P25: 4.3:ShipLane | Q25: Shipping lanes
K26: Southern Ocean | L26: Bahrain | P26: 4.4:FlightPath | Q26: Flight paths
K27: na | L27: Barbados | P27: 4.5.UnspecLine | Q27: Unspecified Transportation & service corridors
L28: Botswana | P28: 5.1:UseAnimals | Q28: Hunting & collecting terrestrial animals
L29: Bermuda | P29: 5.2:UsePlant | Q29: Gathering terrestrial plants
L30: Belgium | P30: 5.3:UseWood | Q30: Logging & wood harvesting
L31: Bahamas, The | P31: 5.4:UseAquatic | Q31: Fishing & harvesting aquatic resources
L32: Bangladesh | P32: 5.5:UseUnspec | Q32: Unspecified Biological resource use
L33: Belize | P33: 6.1:ActivRnR | Q33: Recreational activities
L34: Bosnia and Herzegovina | P34: 6.2:WarConflict | Q34: War, civil unrest & military exercises
L35: Bolivia | P35: 6.3:Other | Q35: Work & other activities
L36: Myanmar (Burma) | P36: 7.1:FireSystem | Q36: Fire & fire suppression
L37: Benin | P37: 7.2:WaterSystem | Q37: Dams & water management/use
L38: Byelarus | P38: 7.3:OtherSystem | Q38: Other ecosystem modifications
L39: Solomon Islands | P39: 8.1:SDAlienInv | Q39: Invasive non-native/alien species/diseases
... L57: Comoros | P57: 12.0:Other | Q57: Other threat
L58: Colombia
L59: Northern Mariana Islands
L60: Costa Rica
...

Sheet Raw -4 (Extended Definitions)
A1: Extended Definitions
A3: 3.1 Study Design
B4: Observational | E4: Variables are not actively manipulated
B5: Experimental | E5: For the sake of this analysis all research which manipulates variables regardless of tightly controlled conditions will be classed as experimental (e.g. exclusion experiments in a natural setting)
B6: S_Review | E6: Systematic review (including meta-analyses). Novel syntheses of data gathered from existing literature.
A7: 3.3 Spatial Scale
B8: Global | E8: The study extent is the whole world
B9: Continental | E9: Study extent covers over 3/4 of a continent or an ocean. This excludes studies of individual countries that encompass > ¾ of the area of the continent (e.g. Australia).
B10: Multi-national | E10: Study extent is defined by the boundary of more than one country, or sites across multiple countries (>10,000km2)
B11: National | E11: Study extent is defined by the boundary of one country
B12: Sub-national | E12: Study extent is larger than 10,000km2 within a single country
B13: Local | E13: Study extent is less than 10,000km2
A14: 3.4 Spatial Resolution Units
B15: The spatial unit used to display the threat map
A16: 3.5 Spatial Resolution
B17: The size of single units that were mapped within the study, rather than the resolution in which data was gathered
A19: 4.1 Threat Metric
B20: PCM | E20: Pre-calculated metric (e.g. Human Footprint Index if accessed as an already computed index)
B21: Database | E21: Existing dataset of human activities or threats to species (e.g. FAO, IUCN, fishing logbook data, repositories of citizen science collected data)
B22: RS | E22: Remotely sensed primary data (Satellite data, aerial surveys, GPS trackers, Remote vessel monitoring systems (VMS). *The use of ground-level camera traps should be classed under ‘survey’)
B23: Literature | E23: Data on threat distribution gathered from existing literature (E.g. Mapping locations of studies that observe threats in a systematic review, using findings from existing peer-reviewed literature or other paper-based sources or archives) E.g. Scraping data from previous published peer-reviewed literature E.g. Scraping data from news reports, paper-based archives or other non-published literature sources )
B24: Survey | E24: Primary collection of data via ground level survey methods to identify presence/absence or intensity of threat (e.g. line transects, camera traps, point counts)
B25: Modelled | E25: Predicted distributions of a current threat based on occurance or susceptibility data (e.g. invasive species or climate change risk)
B26: Expert Judgement | E26: The spatial distribution of threats to species is determined by primary expert elicitation methods (e.g. Interviews, participatory mapping processes, questionnaires)
B27: Other | E27: Any other metric used to determine the spatial distribution of threat to species (e.g. Web scraping Social Media, and data gathered from museum specimens)
A28: 4.6 threat_precision
B29: Cumulative | E29: Individual threats are all mapped together as a single index
B30: Level 1 | E30: Threats are presented individually at the most coarse level of the threat classifcation framework (e.g. Agriculture/Aquaculture, Development, Biological resource use)
B31: Level 2 | E31: Threats are presented individually at a precision greater than level 2 in the threat classifcation framework or finer (e.g. Residential development, livestock farming, hunting)
A32: 5.1 Population Metric
B33: Literature | E33: Secondary data on species distribution gathered from existing literature
B34: Database | E34: Existing dataset of species distributions (e.g. IUCN, or iNaturalist)
B35: Modelled | E35: Predicted distribution of species based on occurance data (e.g. EEO, and habitat suitability modelling)
B36: Survey | E36: Primary data collected on the presence/absence or density of target species through ground-level observations (e.g. line transects, camera traps, point counts)
B37: PCHBA | E37: Pre-calculated high Biodiversity Areas. Identified from previous work to be of high value for biodiversity. E.g. biodiversity hotspots or key biodiversity areas (e.g. Myers 2000 Biodiversity Hotspot, Key Biodiversity areas (Important Bird and Biodiversity Areas, Alliance for zero extinction sites, critical ecosystem partnership)
B38: Protected Area | E38: Any land or sea that is legislatively protected from some or any disturbance (e.g. IUCN PA categories 1a, 1b, 2, and 4, RAMSAR sites, and UNESCO Natural World heritage sites, Marine protected areas)
B39: Expert Judgement | E39: Expert elicitation methods were used to determine the spatial distribution of species within the study area
B40: Other | E40: Any other metric type used to determine the spatial distribution of species within the study area (e.g. social media)
A42: 4.2 Threat data & 5.2 Population data
B43: Quantitative | E43: The measure for population and threat used for each spatial unit is a numeric value. E.g intensity, frequency, density
...

Sheet Enriched
A1: ArticleID | B1: study_design | C1: realm | D1: threats_l1 | E1: threats_l0 | F1: Threat_metric | G1: Pop_metric | H1: tax_kingdom | I1: Continent_Ocean | J1: Country_EEZ | K1: Study_design_orig | L1: Ecoregion | M1: Threat_orig | N1: threat_precision | O1: threat_database | P1: Quantity_threats | Q1: Threat_data | R1: Pop_data | S1: pop_database | T1: animal_group | U1: tax_res | V1: tax_scope | W1: plant_group | X1: Spatial_Scale | Y1: Spatial_res_unit | Z1: Spatial_res | AA1: unspec_other
A2: 24053 | B2: =K2 -> Observational | C2: ["Freshwater"] | D2: ["Housing & urban area"] | E2: ["Residential & commercial development"] | F2: database;expert;rs | G2: survey | H2: animalia | I2: south america | J2: Argentina | K2: Observational | L2: Freshwater | M2: 1.1:DevResid | N2: level1 | O2: ArgentineanGeorgraphicINstitute | P2: 1 | Q2: Qualitative | R2: Quantitative | S2: NA | T2: mammal | U2: species | V2: species | W2: na | X2: Local | Y2: degrees | Z2: 0.05 | AA2: FALSE
A3: 23515 | B3: =K3 -> Observational | C3: ["Marine", "Terrestrial"] | D3: ["Housing & urban area"] | E3: ["Residential & commercial development"] | F3: literature;rs | G3: literature;rs | H3: plantae | I3: indian ocean | J3: Malaysia | K3: Observational | L3: Marine;Terrestrial | M3: 1.1:DevResid | N3: level2 | O3: na | P3: 1 | Q3: Qualitative | R3: qualitative | S3: NA | T3: na | U3: phylum | V3: phylum | W3: mangrove | X3: Local | Y3: polygon | Z3: na | AA3: FALSE
A4: 23795 | B4: =K4 -> Observational | C4: ["Terrestrial"] | D4: ["Housing & urban area"] | E4: ["Residential & commercial development"] | F4: database | G4: literature;modelled | H4: plantae | I4: north america | J4: United States | K4: Observational | L4: Terrestrial | M4: 1.1:DevResid | N4: level2 | O4: US.CensusBureau2014 | P4: 1 | Q4: Qualitative | R4: Qualitative | S4: NA | T4: na | U4: species | V4: genus | W4: magnoliopsida | X4: Sub-national | Y4: km2 | Z4: 1 | AA4: FALSE
A5: 23832 | B5: =K5 -> Observational | C5: ["Terrestrial"] | D5: ["Housing & urban area"] | E5: ["Residential & commercial development"] | F5: rs | G5: database | H5: animalia | I5: asia | J5: na | K5: Observational | L5: Terrestrial | M5: 1.1:DevResid | N5: level2 | O5: NA | P5: 1 | Q5: Qualitative | R5: Qualitative | S5: IUCNredlist | T5: mammal | U5: species | V5: species | W5: na | X5: Continental | Y5: km2 | Z5: 21.16 | AA5: FALSE
A6: 23869 | B6: =K6 -> Observational | C6: ["Terrestrial"] | D6: ["Housing & urban area"] | E6: ["Residential & commercial development"] | F6: rs | G6: literature;rs | H6: plantae | I6: asia | J6: China | K6: Observational | L6: Terrestrial | M6: 1.1:DevResid | N6: level2 | O6: NA | P6: 1 | Q6: Qualitative | R6: Qualitative | S6: NA | T6: na | U6: kingdom | V6: kingdom | W6: habitat | X6: Sub-national | Y6: m | Z6: 30 | AA6: FALSE
A7: 23906 | B7: =K7 -> Observational | C7: ["Terrestrial"] | D7: ["Housing & urban area"] | E7: ["Residential & commercial development"] | F7: database | G7: protected_area | H7: other | I7: europe | J7: Italy | K7: Observational | L7: Terrestrial | M7: 1.1:DevResid | N7: level2 | O7: ItalianMilitaryGeographicalInstitute | P7: 1 | Q7: Qualitative | R7: Qualitative | S7: NA | T7: na | U7: other | V7: other | W7: na | X7: Sub-national | Y7: polygon | Z7: NA | AA7: FALSE
A8: 24418 | B8: =K8 -> Observational | C8: ["Terrestrial"] | D8: ["Housing & urban area"] | E8: ["Residential & commercial development"] | F8: database | G8: survey | H8: plantae | I8: north america | J8: United States | K8: Observational | L8: Terrestrial | M8: 1.1:DevResid | N8: level2 | O8: NA | P8: 1 | Q8: Quantitative | R8: Qualitative | S8: NA | T8: na | U8: kingdom | V8: kingdom | W8: vegetation | X8: Sub-national | Y8: NA | Z8: NA | AA8: FALSE
A9: 24565 | B9: =K9 -> Observational | C9: ["Terrestrial"] | D9: ["Housing & urban area"] | E9: ["Residential & commercial development"] | F9: literature;rs | G9: literature | H9: animalia | I9: asia | J9: China | K9: Observational | L9: Terrestrial | M9: 1.1:DevResid | N9: level2 | O9: na | P9: 1 | Q9: Qualitative | R9: qualitative | S9: NA | T9: bird | U9: genus | V9: genus | W9: na | X9: Local | Y9: polygon | Z9: na | AA9: FALSE
A10: 24667 | B10: =K10 -> Observational | C10: ["Terrestrial"] | D10: ["Housing & urban area"] | E10: ["Residential & commercial development"] | F10: database | G10: literature | H10: plantae | I10: europe | J10: Italy | K10: Observational | L10: Terrestrial | M10: 1.1:DevResid | N10: level2 | O10: NA | P10: 1 | Q10: Qualitative | R10: Qualitative | S10: NA | T10: na | U10: kingdom | V10: kingdom | W10: vegetation | X10: Sub-national | Y10: polygon | Z10: NA | AA10: FALSE
A11: 24748 | B11: =K11 -> Observational | C11: ["Terrestrial"] | D11: ["Housing & urban area"] | E11: ["Residential & commercial development"] | F11: database | G11: pchba;protected_area | H11: other | I11: na | J11: na | K11: Observational | L11: Terrestrial | M11: 1.1:DevResid | N11: level2 | O11: NA | P11: 1 | Q11: Quantitative | R11: Qualitative | S11: NA | T11: na | U11: other | V11: other | W11: na | X11: Global | Y11: polygon | Z11: NA | AA11: FALSE
A12: 24886 | B12: =K12 -> Observational | C12: ["Terrestrial"] | D12: ["Housing & urban area"] | E12: ["Residential & commercial development"] | F12: rs | G12: protected_area | H12: other | I12: africa | J12: Mozambique | K12: Observational | L12: Terrestrial | M12: 1.1:DevResid | N12: level2 | O12: NA | P12: 1 | Q12: Qualitative | R12: Qualitative | S12: NA | T12: na | U12: other | V12: other | W12: na | X12: Local | Y12: m | Z12: 60 | AA12: FALSE
A13: W26588 | B13: =K13 -> Observational | C13: ["Terrestrial"] | D13: ["Housing & urban area"] | E13: ["Residential & commercial development"] | F13: database | G13: pchba | H13: other | I13: na | J13: na | K13: Observational | L13: Terrestrial | M13: 1.1:DevResid | N13: level2 | O13: CCILandCover | P13: 1 | Q13: Quantitative | R13: Qualitative | S13: KBA | T13: na | U13: other | V13: other | W13: na | X13: Global | Y13: polygon | Z13: NA | AA13: FALSE
A14: 23155 | B14: =K14 -> Observational | C14: ["Terrestrial"] | D14: ["Housing & urban area", "Commercial & industrial areas"] | E14: ["Residential & Commercial Development"] | F14: modelled | G14: protected_area | H14: other | I14: europe | J14: Italy | K14: Observational | L14: Terrestrial | M14: 1.1:DevResid;1.2:DevComInd | N14: level1 | O14: NA | P14: 2 | Q14: Quantitative | R14: Qualitative | S14: NA | T14: na | U14: other | V14: other | W14: na | X14: National | Y14: polygon | Z14: na | AA14: FALSE
A15: 23938 | B15: =K15 -> Observational | C15: ["Terrestrial"] | D15: ["Housing & urban area", "Commercial & industrial areas", "Tourism & recreation areas", "Annual & perennial non-timber crops", "Wood & pulp plantations", "Livestock farming & ranching", "Roads & railroads"] | E15: ["Residential & Commercial Development", "Agriculture & Aquaculture", "Transportation & Service Corridors"] | F15: database;rs | G15: database | H15: animalia | I15: europe | J15: Italy | K15: Observational | L15: Terrestrial | M15: 1.1:DevResid;1.2:DevComInd;1.3:DevRnR;2.1:AgNTC;2.2:AgWood;2.3:AgLivestock;4.1:RoadRail | N15: level1 | O15: CorineLandCover | P15: 7 | Q15: Qualitative | R15: Quantitative | S15: NationalEcologicalNetwork | T15: mammal | U15: class | V15: class | W15: na | X15: Local | Y15: polygon | Z15: NA | AA15: FALSE
A16: 23071 | B16: =K16 -> Observational | C16: ["Terrestrial"] | D16: ["Housing & urban area", "Commercial & industrial areas", "Tourism & recreation areas", "Annual & perennial non-timber crops", "Livestock farming & ranching", "Roads & railroads", "Excess energy"] | E16: ["Residential & Commercial Development", "Agriculture & Aquaculture", "Transportation & Service Corridors", "Pollution"] | F16: pcm | G16: protected_area | H16: other | I16: na | J16: na | K16: Observational | L16: Terrestrial | M16: 1.1:DevResid;1.2:DevComInd;1.3:DevRnR;2.1:AgNTC;2.3:AgLivestock;4.1:RoadRail;9.6:PollEnergy | N16: cumulative | O16: HFI | P16: 7 | Q16: Quantitative | R16: Qualitative | S16: NaturalWorldHeritage | T16: na | U16: other | V16: other | W16: na | X16: Global | Y16: polygon | Z16: NA | AA16: FALSE
A17: 23399 | B17: =K17 -> Observational | C17: ["Terrestrial"] | D17: ["Housing & urban area", "Commercial & industrial areas", "Tourism & recreation areas", "Annual & perennial non-timber crops", "Livestock farming & ranching", "Roads & railroads", "Excess energy"] | E17: ["Residential & Commercial Development", "Agriculture & Aquaculture", "Transportation & Service Corridors", "Pollution"] | F17: database | G17: protected_area | H17: other | I17: asia | J17: China | K17: Observational | L17: Terrestrial | M17: 1.1:DevResid;1.2:DevComInd;1.3:DevRnR;2.1:AgNTC;2.3:AgLivestock;4.1:RoadRail;9.6:PollEnergy | N17: cumulative | O17: NA | P17: 7 | Q17: Quantitative | R17: Qualitative | S17: NA | T17: na | U17: other | V17: other | W17: na | X17: National | Y17: km2 | Z17: 1 | AA17: FALSE
A18: 23657 | B18: =K18 -> Observational | C18: ["Terrestrial"] | D18: ["Housing & urban area", "Commercial & industrial areas", "Tourism & recreation areas", "Annual & perennial non-timber crops", "Livestock farming & ranching", "Roads & railroads", "Excess energy"] | E18: ["Residential & Commercial Development", "Agriculture & Aquaculture", "Transportation & Service Corridors", "Pollution"] | F18: modelled | G18: rs | H18: plantae | I18: asia | J18: China | K18: Observational | L18: Terrestrial | M18: 1.1:DevResid;1.2:DevComInd;1.3:DevRnR;2.1:AgNTC;2.3:AgLivestock;4.1:RoadRail;9.6:PollEnergy | N18: cumulative | O18: HFI;resdc.cn | P18: 7 | Q18: Quantitative | R18: Qualitative | S18: NA | T18: na | U18: kingdom | V18: kingdom | W18: habitat | X18: Sub-national | Y18: km2 | Z18: 1 | AA18: FALSE
A19: 23726 | B19: =K19 -> Observational | C19: ["Terrestrial"] | D19: ["Housing & urban area", "Commercial & industrial areas", "Tourism & recreation areas", "Annual & perennial non-timber crops", "Livestock farming & ranching", "Roads & railroads", "Excess energy"] | E19: ["Residential & Commercial Development", "Agriculture & Aquaculture", "Transportation & Service Corridors", "Pollution"] | F19: pcm | G19: database | H19: animalia | I19: na | J19: na | K19: Observational | L19: Terrestrial | M19: 1.1:DevResid;1.2:DevComInd;1.3:DevRnR;2.1:AgNTC;2.3:AgLivestock;4.1:RoadRail;9.6:PollEnergy | N19: cumulative | O19: HFI | P19: 7 | Q19: Quantitative | R19: Qualitative | S19: IUCNredlist | T19: mammal | U19: class | V19: class | W19: na | X19: Global | Y19: km2 | Z19: 1 | AA19: FALSE
A20: 24108 | B20: =K20 -> Observational | C20: ["Terrestrial"] | D20: ["Housing & urban area", "Commercial & industrial areas", "Tourism & recreation areas", "Annual & perennial non-timber crops", "Livestock farming & ranching", "Roads & railroads", "Excess energy"] | E20: ["Residential & Commercial Development", "Agriculture & Aquaculture", "Transportation & Service Corridors", "Pollution"] | F20: pcm | G20: database | H20: animalia | I20: na | J20: na | K20: Observational | L20: Terrestrial | M20: 1.1:DevResid;1.2:DevComInd;1.3:DevRnR;2.1:AgNTC;2.3:AgLivestock;4.1:RoadRail;9.6:PollEnergy | N20: cumulative | O20: HFI | P20: 7 | Q20: Quantitative | R20: Quantitative | S20: GARD_GlobalAssessmentOfReptileDistributions | T20: reptile | U20: class | V20: class | W20: na | X20: Global | Y20: degrees | Z20: 1 | AA20: FALSE
A21: 25734 | B21: =K21 -> Observational | C21: ["Terrestrial"] | D21: ["Housing & urban area", "Commercial & industrial areas", "Tourism & recreation areas", "Annual & perennial non-timber crops", "Livestock farming & ranching", "Roads & railroads", "Excess energy"] | E21: ["Residential & Commercial Development", "Agriculture & Aquaculture", "Transportation & Service Corridors", "Pollution"] | F21: database | G21: protected_area | H21: other | I21: south america | J21: Ecuador | K21: Observational | L21: Terrestrial | M21: 1.1:DevResid;1.2:DevComInd;1.3:DevRnR;2.1:AgNTC;2.3:AgLivestock;4.1:RoadRail;9.6:PollEnergy | N21: cumulative | O21: Various | P21: 7 | Q21: Quantitative | R21: Qualitative | S21: NA | T21: na | U21: other | V21: other | W21: na | X21: Sub-national | Y21: m | Z21: 100 | AA21: FALSE
A22: 25830 | B22: =K22 -> Observational | C22: ["Terrestrial"] | D22: ["Housing & urban area", "Commercial & industrial areas", "Tourism & recreation areas", "Annual & perennial non-timber crops", "Livestock farming & ranching", "Roads & railroads", "Excess energy"] | E22: ["Residential & Commercial Development", "Agriculture & Aquaculture", "Transportation & Service Corridors", "Pollution"] | F22: pcm | G22: database;rs | H22: animalia | I22: na | J22: na | K22: Observational | L22: Terrestrial | M22: 1.1:DevResid;1.2:DevComInd;1.3:DevRnR;2.1:AgNTC;2.3:AgLivestock;4.1:RoadRail;9.6:PollEnergy | N22: cumulative | O22: HFI_Venter2016 | P22: 7 | Q22: Quantitative | R22: Qualitative | S22: MoveBank | T22: mammal | U22: class | V22: class | W22: na | X22: Global | Y22: km2 | Z22: 1 | AA22: FALSE
A23: 24314 | B23: =K23 -> Observational | C23: ["Terrestrial"] | D23: ["Housing & urban area", "Commercial & industrial areas", "Tourism & recreation areas", "Annual & perennial non-timber crops", "Livestock farming & ranching", "Roads & railroads", "Excess energy", "Excess energy"] | E23: ["Residential & Commercial Development", "Agriculture & Aquaculture", "Transportation & Service Corridors", "Pollution"] | F23: database;rs | G23: protected_area | H23: other | I23: north america | J23: United States | K23: Observational | L23: Terrestrial | M23: 1.1:DevResid;1.2:DevComInd;1.3:DevRnR;2.1:AgNTC;2.3:AgLivestock;4.1:RoadRail;9.6:PollEnergy;9.6:PollEnergy | N23: level2 | O23: DMSP-OLS | P23: 7 | Q23: Quantitative | R23: qualitative | S23: NA | T23: na | U23: other | V23: other | W23: na | X23: Sub-national | Y23: km2 | Z23: 1 | AA23: FALSE
A24: 23135 | B24: =K24 -> Observational | C24: ["Marine"] | D24: ["Housing & urban area", "Commercial & industrial areas", "Tourism & recreation areas", "Marine & freshwater aquaculture", "Oil & gas drilling", "Shipping lanes", "Fishing & harvesting aquatic resources", "Agricultural & forestry effluents", "Mining & quarrying", "Recreational activities"] | E24: ["Residential & Commercial Development", "Agriculture & Aquaculture", "Energy Production & Mining", "Transportation & Service Corridors", "Biological Resource Use", "Pollution", "Human Intrusions & Disturbance"] | F24: expert;modelled | G24: expert | H24: animalia;plantae | I24: north atlantic | J24: Belize | K24: Observational | L24: Marine | M24: 1.1:DevResid;1.2:DevComInd;1.3:DevRnR;2.4:Aqua;3.1:OilGas;4.3:ShipLane;5.4:UseAquatic;9.3:PollAgrFor;3.2:MinQuar;6.1:ActivRnR | N24: level2 | O24: NA | P24: 10 | Q24: Quantitative | R24: Qualitative | S24: NA | T24: invertebrates | U24: class | V24: domain | W24: mangrove;liliopsida | X24: National | Y24: m | Z24: 500 | AA24: FALSE
A25: 26127 | B25: =K25 -> Observational | C25: ["Marine"] | D25: ["Housing & urban area", "Commercial & industrial areas", "Habitat shifting & alteration", "Temperature extremes", "Oil & gas drilling", "Shipping lanes", "Fishing & harvesting aquatic resources", "Invasive non-native/alien species/diseases", "Industrial & military effluents", "Agricultural & forestry effluents", "Excess energy"] | E25: ["Residential & Commercial Development", "Climate Change & Severe Weather", "Energy Production & Mining", "Transportation & Service Corridors", "Biological Resource Use", "Invasive & Other Problematic Species, Genes & Diseases", "Pollution"] | F25: expert;literature;modelled | G25: expert;literature | H25: animalia | I25: na | J25: na | K25: Observational | L25: Marine | M25: 1.1:DevResid;1.2:DevComInd;11.1:CC_Habitat;11.3:CC_Temp;3.1:OilGas;4.3:ShipLane;5.4:UseAquatic;8.1:SDAlienInv;9.2:PollIndMil;9.3:PollAgrFor;9.6:PollEnergy | N25: level2 | O25: na | P25: 11 | Q25: Quantitative | R25: qualitative | S25: NA | T25: Fish | U25: genus | V25: genus | W25: na | X25: Global | Y25: km2 | Z25: 1 | AA25: FALSE
A26: 24842 | B26: =K26 -> Observational | C26: ["Terrestrial"] | D26: ["Housing & urban area", "Commercial & industrial areas", "Annual & perennial non-timber crops", "Wood & pulp plantations"] | E26: ["Residential & Commercial Development", "Agriculture & Aquaculture"] | F26: rs | G26: rs | H26: plantae | I26: asia | J26: India | K26: Observational | L26: Terrestrial | M26: 1.1:DevResid;1.2:DevComInd;2.1:AgNTC;2.2:AgWood | N26: level2 | O26: NA | P26: 4 | Q26: Qualitative | R26: Qualitative | S26: NA | T26: na | U26: kingdom | V26: kingdom | W26: forest;habitat | X26: Sub-national | Y26: NA | Z26: NA | AA26: FALSE
A27: 23125 | B27: =K27 -> Observational | C27: ["Terrestrial"] | D27: ["Housing & urban area", "Commercial & industrial areas", "Annual & perennial non-timber crops", "Livestock farming & ranching"] | E27: ["Residential & Commercial Development", "Agriculture & Aquaculture"] | F27: database | G27: modelled | H27: animalia;plantae | I27: europe | J27: na | K27: Observational | L27: Terrestrial | M27: 1.1:DevResid;1.2:DevComInd;2.1:AgNTC;2.3:AgLivestock | N27: level2 | O27: Eurostat2000 | P27: 3 | Q27: Quantitative | R27: Qualitative | S27: NA | T27: bird;mammal;reptile;amphibia | U27: class | V27: domain | W27: tracheophyta | X27: Continental | Y27: km2 | Z27: 50 | AA27: FALSE
A28: 25077 | B28: =K28 -> Observational | C28: ["Terrestrial"] | D28: ["Housing & urban area", "Commercial & industrial areas", "Annual & perennial non-timber crops", "Livestock farming & ranching", "Oil & gas drilling", "Mining & quarrying", "Roads & railroads", "Utility & service lines", "Dams & water management/use"] | E28: ["Residential & Commercial Development", "Agriculture & Aquaculture", "Energy Production & Mining", "Transportation & Service Corridors", "Natural System Modifications"] | F28: rs | G28: literature | H28: animalia | I28: north america | J28: Canada | K28: Observational | L28: Terrestrial | M28: 1.1:DevResid;1.2:DevComInd;2.1:AgNTC;2.3:AgLivestock;3.1:OilGas;3.2:MinQuar;4.1:RoadRail;4.2:UtilityLine;7.2:WaterSystem | N28: level2 | O28: na | P28: 10 | Q28: Qualitative | R28: qualitative | S28: CaribouScienceAssessmnet | T28: mammal | U28: species | V28: species | W28: na | X28: Sub-national | Y28: m | Z28: 30 | AA28: FALSE
A29: 23072 | B29: =K29 -> Observational | C29: ["Terrestrial"] | D29: ["Housing & urban area", "Commercial & industrial areas", "Annual & perennial non-timber crops", "Livestock farming & ranching", "Roads & railroads", "Utility & service lines", "Hunting & collecting terrestrial animals", "Gathering terrestrial plants", "Recreational activities", "Work & other activities", "Invasive non-native/alien species/diseases", "Domestic & urban waste water", "Agricultural & forestry effluents", "Garbage & solid waste", "Excess energy"] | E29: ["Residential & Commercial Development", "Agriculture & Aquaculture", "Transportation & Service Corridors", "Biological Resource Use", "Human Intrusions & Disturbance", "Invasive & Other Problematic Species, Genes & Diseases", "Pollution"] | F29: pcm | G29: database | H29: animalia | I29: na | J29: na | K29: Observational | L29: Terrestrial | M29: 1.1:DevResid;1.2:DevComInd;2.1:AgNTC;2.3:AgLivestock;4.1:RoadRail;4.2:UtilityLine;5.1:UseAnimals;5.2:UsePlant;6.1:ActivRnR;6.3:Other;8.1:SDAlienInv;9.1:PollDWW;9.3:PollAgrFor;9.4:PollGarbSW;9.6:PollEnergy | N29: cumulative | O29: HFI | P29: 15 | Q29: Quantitative | R29: Quantitative | S29: IUCN | T29: mammal;amphibia;bird | U29: phylum | V29: phylum | W29: na | X29: Global | Y29: km2 | Z29: 30 | AA29: FALSE
A30: 23477 | B30: =K30 -> Observational | C30: ["Terrestrial"] | D30: ["Housing & urban area", "Commercial & industrial areas", "Annual & perennial non-timber crops", "Livestock farming & ranching", "Dams & water management/use"] | E30: ["Residential & Commercial Development", "Agriculture & Aquaculture", "Natural System Modifications"] | F30: rs | G30: rs | H30: plantae | I30: south america | J30: Brazil | K30: Observational | L30: Terrestrial | M30: 1.1:DevResid;1.2:DevComInd;2.1:AgNTC;2.3:AgLivestock;7.2:WaterSystem | N30: level2 | O30: TerraClassInitiative_TC; Landsat | P30: 5 | Q30: Qualitative | R30: qualitative | S30: NA | T30: na | U30: kingdom | V30: kingdom | W30: forest | X30: Sub-national | Y30: km2 | Z30: 100 | AA30: FALSE
